{"total_count": 38, "incomplete_results": false, "items": [{"url": "https://api.github.com/repos/launchdarkly/python-server-sdk/issues/143", "repository_url": "https://api.github.com/repos/launchdarkly/python-server-sdk", "labels_url": "https://api.github.com/repos/launchdarkly/python-server-sdk/issues/143/labels{/name}", "comments_url": "https://api.github.com/repos/launchdarkly/python-server-sdk/issues/143/comments", "events_url": "https://api.github.com/repos/launchdarkly/python-server-sdk/issues/143/events", "html_url": "https://github.com/launchdarkly/python-server-sdk/issues/143", "id": 605690742, "node_id": "MDU6SXNzdWU2MDU2OTA3NDI=", "number": 143, "title": "Unexpected keyword argument 'total' prevents events from being sent", "user": {"login": "mrdon", "id": 18610, "node_id": "MDQ6VXNlcjE4NjEw", "avatar_url": "https://avatars3.githubusercontent.com/u/18610?v=4", "gravatar_id": "", "url": "https://api.github.com/users/mrdon", "html_url": "https://github.com/mrdon", "followers_url": "https://api.github.com/users/mrdon/followers", "following_url": "https://api.github.com/users/mrdon/following{/other_user}", "gists_url": "https://api.github.com/users/mrdon/gists{/gist_id}", "starred_url": "https://api.github.com/users/mrdon/starred{/owner}{/repo}", "subscriptions_url": "https://api.github.com/users/mrdon/subscriptions", "organizations_url": "https://api.github.com/users/mrdon/orgs", "repos_url": "https://api.github.com/users/mrdon/repos", "events_url": "https://api.github.com/users/mrdon/events{/privacy}", "received_events_url": "https://api.github.com/users/mrdon/received_events", "type": "User", "site_admin": false}, "labels": [], "state": "closed", "locked": false, "assignee": null, "assignees": [], "milestone": null, "comments": 9, "created_at": "2020-04-23T16:51:44Z", "updated_at": "2020-07-30T20:20:12Z", "closed_at": "2020-07-13T20:33:30Z", "author_association": "CONTRIBUTOR", "active_lock_reason": null, "body": "Occasionally, I see this in the logs:\r\n\r\nUnhandled exception in event processor. Analytics events were not processed. [__init__() got an unexpected keyword argument 'total']\r\n\r\nIt doesn't happen all the time, and I think I traced it down to how retries are handled.  This library uses a _EventRetry subclass of urllib3.Retry, however, Retry will try to recreate itself via the \"new\" function, passing in all the arguments it received.  Unfortunately, _EventRetry doesn't support any of those arguments, specifically 'total', and I think this is causing the error.\r\n\r\nThe fix would be to, at a minimum, add **kwargs to the constructor, or better yet, pass those same arguments down.", "performed_via_github_app": null, "score": 1.0}, {"url": "https://api.github.com/repos/launchdarkly/python-server-sdk/issues/136", "repository_url": "https://api.github.com/repos/launchdarkly/python-server-sdk", "labels_url": "https://api.github.com/repos/launchdarkly/python-server-sdk/issues/136/labels{/name}", "comments_url": "https://api.github.com/repos/launchdarkly/python-server-sdk/issues/136/comments", "events_url": "https://api.github.com/repos/launchdarkly/python-server-sdk/issues/136/events", "html_url": "https://github.com/launchdarkly/python-server-sdk/issues/136", "id": 532807200, "node_id": "MDU6SXNzdWU1MzI4MDcyMDA=", "number": 136, "title": "YAMLLoadWarning", "user": {"login": "OisinMoran", "id": 8939851, "node_id": "MDQ6VXNlcjg5Mzk4NTE=", "avatar_url": "https://avatars2.githubusercontent.com/u/8939851?v=4", "gravatar_id": "", "url": "https://api.github.com/users/OisinMoran", "html_url": "https://github.com/OisinMoran", "followers_url": "https://api.github.com/users/OisinMoran/followers", "following_url": "https://api.github.com/users/OisinMoran/following{/other_user}", "gists_url": "https://api.github.com/users/OisinMoran/gists{/gist_id}", "starred_url": "https://api.github.com/users/OisinMoran/starred{/owner}{/repo}", "subscriptions_url": "https://api.github.com/users/OisinMoran/subscriptions", "organizations_url": "https://api.github.com/users/OisinMoran/orgs", "repos_url": "https://api.github.com/users/OisinMoran/repos", "events_url": "https://api.github.com/users/OisinMoran/events{/privacy}", "received_events_url": "https://api.github.com/users/OisinMoran/received_events", "type": "User", "site_admin": false}, "labels": [], "state": "closed", "locked": false, "assignee": null, "assignees": [], "milestone": null, "comments": 9, "created_at": "2019-12-04T16:47:48Z", "updated_at": "2019-12-10T00:13:14Z", "closed_at": "2019-12-04T18:52:26Z", "author_association": "NONE", "active_lock_reason": null, "body": "**Is this a support request?**\r\nNo\r\n\r\n**Describe the bug**\r\nUsing Launch Darkly in Python 3.6 gives the following warning:\r\n\r\n```\r\nYAMLLoadWarning: calling yaml.load() without Loader=... is deprecated ...\r\n```\r\n\r\nFurther details can be found here:\r\nhttps://github.com/yaml/pyyaml/wiki/PyYAML-yaml.load(input)-Deprecation\r\n\r\nIs there a plan to update this?\r\n\r\n**To reproduce**\r\n```\r\nimport ldclient\r\nldclient.get().variation(...)\r\n```\r\n\r\n**Expected behavior**\r\nNo warnings\r\n\r\n**Logs**\r\n```\r\nYAMLLoadWarning: calling yaml.load() without Loader=... is deprecated, as the \r\ndefault Loader is unsafe. Please read https://msg.pyyaml.org/load for full details.\r\n```\r\n\r\n**SDK version**\r\n`launchdarkly-server-sdk==6.11.1`\r\n\r\n**Language version, developer tools**\r\nPython 3.6\r\n\r\n**OS/platform**\r\nUbuntu 18.04\r\n\r\n**Additional context**\r\nNone\r\n", "performed_via_github_app": null, "score": 1.0}, {"url": "https://api.github.com/repos/launchdarkly/python-server-sdk/issues/135", "repository_url": "https://api.github.com/repos/launchdarkly/python-server-sdk", "labels_url": "https://api.github.com/repos/launchdarkly/python-server-sdk/issues/135/labels{/name}", "comments_url": "https://api.github.com/repos/launchdarkly/python-server-sdk/issues/135/comments", "events_url": "https://api.github.com/repos/launchdarkly/python-server-sdk/issues/135/events", "html_url": "https://github.com/launchdarkly/python-server-sdk/issues/135", "id": 526824858, "node_id": "MDU6SXNzdWU1MjY4MjQ4NTg=", "number": 135, "title": "TypeError: backoff.on_exception when running in uvicorn", "user": {"login": "dj0nes", "id": 1503413, "node_id": "MDQ6VXNlcjE1MDM0MTM=", "avatar_url": "https://avatars2.githubusercontent.com/u/1503413?v=4", "gravatar_id": "", "url": "https://api.github.com/users/dj0nes", "html_url": "https://github.com/dj0nes", "followers_url": "https://api.github.com/users/dj0nes/followers", "following_url": "https://api.github.com/users/dj0nes/following{/other_user}", "gists_url": "https://api.github.com/users/dj0nes/gists{/gist_id}", "starred_url": "https://api.github.com/users/dj0nes/starred{/owner}{/repo}", "subscriptions_url": "https://api.github.com/users/dj0nes/subscriptions", "organizations_url": "https://api.github.com/users/dj0nes/orgs", "repos_url": "https://api.github.com/users/dj0nes/repos", "events_url": "https://api.github.com/users/dj0nes/events{/privacy}", "received_events_url": "https://api.github.com/users/dj0nes/received_events", "type": "User", "site_admin": false}, "labels": [], "state": "closed", "locked": false, "assignee": null, "assignees": [], "milestone": null, "comments": 3, "created_at": "2019-11-21T20:29:56Z", "updated_at": "2020-02-04T16:25:03Z", "closed_at": "2019-11-22T18:32:36Z", "author_association": "NONE", "active_lock_reason": null, "body": "**Describe the bug**\r\nI noticed the following error when trying to use launch darkly in a fastapi project with code reloading:\r\n\r\n```\r\nTypeError: backoff.on_exception applied to a regular function inside coroutine, this will lead to event loop hiccups. Use backoff.on_exception on coroutines in asynchronous code.\r\n```\r\n\r\nThe error is thrown from [this line](https://github.com/launchdarkly/python-server-sdk/blob/8adfe4c1607ca5a890b436491d9bec77ed2e1b6f/ldclient/streaming.py#L85) in python-server-sdk.\r\n\r\n\r\nThe command to run uvicorn is [here](https://github.com/tiangolo/uvicorn-gunicorn-docker/blob/8e690ce601f28d204411c48749943653c48ffe59/python3.7-alpine3.8/start-reload.sh#L28) in the base image.\r\n\r\n**To reproduce**\r\nI created a [simple repo](https://github.com/dj0nes/ldclient-uvicorn-issue) to reproduce the issue.\r\n\r\n```bash\r\ngit clone https://github.com/dj0nes/ldclient-uvicorn-issue.git\r\ndocker-compose up\r\n```\r\n\r\n**Expected behavior**\r\nThe application should run without crashing.\r\n\r\n**SDK version**\r\n`launchdarkly-server-sdk~=6.11.1`\r\n\r\n**Language version, developer tools**\r\npython 3.7\r\n\r\n**OS/platform**\r\nalpine 3.8\r\n", "performed_via_github_app": null, "score": 1.0}, {"url": "https://api.github.com/repos/launchdarkly/python-server-sdk/issues/125", "repository_url": "https://api.github.com/repos/launchdarkly/python-server-sdk", "labels_url": "https://api.github.com/repos/launchdarkly/python-server-sdk/issues/125/labels{/name}", "comments_url": "https://api.github.com/repos/launchdarkly/python-server-sdk/issues/125/comments", "events_url": "https://api.github.com/repos/launchdarkly/python-server-sdk/issues/125/events", "html_url": "https://github.com/launchdarkly/python-server-sdk/issues/125", "id": 454833331, "node_id": "MDU6SXNzdWU0NTQ4MzMzMzE=", "number": 125, "title": "DeprecationWarning The 'warn' method", "user": {"login": "KKomarov", "id": 14128194, "node_id": "MDQ6VXNlcjE0MTI4MTk0", "avatar_url": "https://avatars0.githubusercontent.com/u/14128194?v=4", "gravatar_id": "", "url": "https://api.github.com/users/KKomarov", "html_url": "https://github.com/KKomarov", "followers_url": "https://api.github.com/users/KKomarov/followers", "following_url": "https://api.github.com/users/KKomarov/following{/other_user}", "gists_url": "https://api.github.com/users/KKomarov/gists{/gist_id}", "starred_url": "https://api.github.com/users/KKomarov/starred{/owner}{/repo}", "subscriptions_url": "https://api.github.com/users/KKomarov/subscriptions", "organizations_url": "https://api.github.com/users/KKomarov/orgs", "repos_url": "https://api.github.com/users/KKomarov/repos", "events_url": "https://api.github.com/users/KKomarov/events{/privacy}", "received_events_url": "https://api.github.com/users/KKomarov/received_events", "type": "User", "site_admin": false}, "labels": [], "state": "closed", "locked": false, "assignee": null, "assignees": [], "milestone": null, "comments": 4, "created_at": "2019-06-11T18:13:52Z", "updated_at": "2019-06-20T12:12:42Z", "closed_at": "2019-06-11T21:49:00Z", "author_association": "NONE", "active_lock_reason": null, "body": "6.9.1 version, I got deprecation warning about `warn`. Can you fix these annoying messages?\r\n```\r\nC:\\Python37\\lib\\site-packages\\ldclient\\client.py:287: DeprecationWarning: The 'warn' method is deprecated, use 'warning' instead\r\n    + str(default) + \" for feature key: \" + key)\r\n```", "performed_via_github_app": null, "score": 1.0}, {"url": "https://api.github.com/repos/launchdarkly/python-server-sdk/issues/124", "repository_url": "https://api.github.com/repos/launchdarkly/python-server-sdk", "labels_url": "https://api.github.com/repos/launchdarkly/python-server-sdk/issues/124/labels{/name}", "comments_url": "https://api.github.com/repos/launchdarkly/python-server-sdk/issues/124/comments", "events_url": "https://api.github.com/repos/launchdarkly/python-server-sdk/issues/124/events", "html_url": "https://github.com/launchdarkly/python-server-sdk/issues/124", "id": 450484220, "node_id": "MDU6SXNzdWU0NTA0ODQyMjA=", "number": 124, "title": "Log warning on every analytics bulk POST", "user": {"login": "mrdon-reciprocity", "id": 47197899, "node_id": "MDQ6VXNlcjQ3MTk3ODk5", "avatar_url": "https://avatars2.githubusercontent.com/u/47197899?v=4", "gravatar_id": "", "url": "https://api.github.com/users/mrdon-reciprocity", "html_url": "https://github.com/mrdon-reciprocity", "followers_url": "https://api.github.com/users/mrdon-reciprocity/followers", "following_url": "https://api.github.com/users/mrdon-reciprocity/following{/other_user}", "gists_url": "https://api.github.com/users/mrdon-reciprocity/gists{/gist_id}", "starred_url": "https://api.github.com/users/mrdon-reciprocity/starred{/owner}{/repo}", "subscriptions_url": "https://api.github.com/users/mrdon-reciprocity/subscriptions", "organizations_url": "https://api.github.com/users/mrdon-reciprocity/orgs", "repos_url": "https://api.github.com/users/mrdon-reciprocity/repos", "events_url": "https://api.github.com/users/mrdon-reciprocity/events{/privacy}", "received_events_url": "https://api.github.com/users/mrdon-reciprocity/received_events", "type": "User", "site_admin": false}, "labels": [], "state": "closed", "locked": false, "assignee": null, "assignees": [], "milestone": null, "comments": 6, "created_at": "2019-05-30T20:10:00Z", "updated_at": "2020-03-26T22:10:14Z", "closed_at": "2019-06-03T21:32:30Z", "author_association": "NONE", "active_lock_reason": null, "body": "Seemingly every time the library sends bulk analytic data back, the following error is logged as a warning:\r\n\r\nUnhandled exception in event processor. Analytics events were not processed. ('Connection aborted.', RemoteDisconnected('Remote end closed connection without response'))\r\n\r\nIt doesn't seem to affect either the performance of the library or even the analytics as viewed in the Launchdarkly web UI.  \r\n\r\nIt seems to have started on May 21st, which doesn't correspond to any library upgrades on our side.  We are running the latest 6.9.2\r\n", "performed_via_github_app": null, "score": 1.0}, {"url": "https://api.github.com/repos/launchdarkly/python-server-sdk/issues/118", "repository_url": "https://api.github.com/repos/launchdarkly/python-server-sdk", "labels_url": "https://api.github.com/repos/launchdarkly/python-server-sdk/issues/118/labels{/name}", "comments_url": "https://api.github.com/repos/launchdarkly/python-server-sdk/issues/118/comments", "events_url": "https://api.github.com/repos/launchdarkly/python-server-sdk/issues/118/events", "html_url": "https://github.com/launchdarkly/python-server-sdk/issues/118", "id": 430614864, "node_id": "MDU6SXNzdWU0MzA2MTQ4NjQ=", "number": 118, "title": "Error closing client when LaunchDarkly relay proxy in daemon mode", "user": {"login": "benpagedelphix", "id": 47989039, "node_id": "MDQ6VXNlcjQ3OTg5MDM5", "avatar_url": "https://avatars2.githubusercontent.com/u/47989039?v=4", "gravatar_id": "", "url": "https://api.github.com/users/benpagedelphix", "html_url": "https://github.com/benpagedelphix", "followers_url": "https://api.github.com/users/benpagedelphix/followers", "following_url": "https://api.github.com/users/benpagedelphix/following{/other_user}", "gists_url": "https://api.github.com/users/benpagedelphix/gists{/gist_id}", "starred_url": "https://api.github.com/users/benpagedelphix/starred{/owner}{/repo}", "subscriptions_url": "https://api.github.com/users/benpagedelphix/subscriptions", "organizations_url": "https://api.github.com/users/benpagedelphix/orgs", "repos_url": "https://api.github.com/users/benpagedelphix/repos", "events_url": "https://api.github.com/users/benpagedelphix/events{/privacy}", "received_events_url": "https://api.github.com/users/benpagedelphix/received_events", "type": "User", "site_admin": false}, "labels": [], "state": "closed", "locked": false, "assignee": null, "assignees": [], "milestone": null, "comments": 2, "created_at": "2019-04-08T19:16:49Z", "updated_at": "2019-04-10T00:11:54Z", "closed_at": "2019-04-10T00:11:54Z", "author_association": "NONE", "active_lock_reason": null, "body": "**Describe the bug**\r\nUsing LaunchDarkly relay proxy in daemon mode (`use_ldd=True`) causes the following error whenever the client is closed.\r\n\r\n```\r\n'LDClient' object has no attribute '_update_processor': AttributeError\r\nTraceback (most recent call last):\r\n...\r\n    client.close()\r\n  File \"/var/task/ldclient/client.py\", line 160, in close\r\n    if self._update_processor and self._update_processor.is_alive():\r\nAttributeError: 'LDClient' object has no attribute '_update_processor'\r\n```\r\nNote that this can also be triggered by calling `ldclient.set_config(config)`.\r\n\r\nThe issue is that because we are running in daemon mode, the  `_update_processor` attribute for the client was never set. The following lines from `ldclient.client.LDClient#__init__` capture this.\r\n\r\n```python\r\nif self._config.use_ldd:\r\n            log.info(\"Started LaunchDarkly Client in LDD mode\")\r\n            return\r\n```\r\nbut the `_update_processor` attribute is not set until later in the object initialization.\r\n\r\n**To reproduce**\r\n\r\nCreate a client with a config that has `use_ldd` set to `True` and try to call `close` on that client.\r\n\r\n**Expected behavior**\r\n\r\nThe client should close the connection without an issue.\r\n\r\n**Logs**\r\n```\r\n'LDClient' object has no attribute '_update_processor': AttributeError\r\nTraceback (most recent call last):\r\n...\r\nldclient.set_config(config)\r\nFile \"/var/task/ldclient/__init__.py\", line 47, in set_config\r\nold_client.close()\r\nFile \"/var/task/ldclient/client.py\", line 160, in close\r\nif self._update_processor and self._update_processor.is_alive():\r\nAttributeError: 'LDClient' object has no attribute '_update_processor'\r\n```\r\n\r\n**SDK version**\r\n6.8.4\r\n\r\n**Language version, developer tools**\r\nPython 3.6\r\n\r\n**Additional context**\r\nI discovered this while using the SDK in a lambda function. Even though it was a new call to the lambda, calling `ldclient.set_config` caused the client from the previous run to try to close, which caused this issue.", "performed_via_github_app": null, "score": 1.0}, {"url": "https://api.github.com/repos/launchdarkly/python-server-sdk/issues/115", "repository_url": "https://api.github.com/repos/launchdarkly/python-server-sdk", "labels_url": "https://api.github.com/repos/launchdarkly/python-server-sdk/issues/115/labels{/name}", "comments_url": "https://api.github.com/repos/launchdarkly/python-server-sdk/issues/115/comments", "events_url": "https://api.github.com/repos/launchdarkly/python-server-sdk/issues/115/events", "html_url": "https://github.com/launchdarkly/python-server-sdk/issues/115", "id": 427138646, "node_id": "MDU6SXNzdWU0MjcxMzg2NDY=", "number": 115, "title": "setting user attributes to non-strings when strings are expected can cause problems", "user": {"login": "eli-darkly", "id": 35503443, "node_id": "MDQ6VXNlcjM1NTAzNDQz", "avatar_url": "https://avatars0.githubusercontent.com/u/35503443?v=4", "gravatar_id": "", "url": "https://api.github.com/users/eli-darkly", "html_url": "https://github.com/eli-darkly", "followers_url": "https://api.github.com/users/eli-darkly/followers", "following_url": "https://api.github.com/users/eli-darkly/following{/other_user}", "gists_url": "https://api.github.com/users/eli-darkly/gists{/gist_id}", "starred_url": "https://api.github.com/users/eli-darkly/starred{/owner}{/repo}", "subscriptions_url": "https://api.github.com/users/eli-darkly/subscriptions", "organizations_url": "https://api.github.com/users/eli-darkly/orgs", "repos_url": "https://api.github.com/users/eli-darkly/repos", "events_url": "https://api.github.com/users/eli-darkly/events{/privacy}", "received_events_url": "https://api.github.com/users/eli-darkly/received_events", "type": "User", "site_admin": false}, "labels": [], "state": "closed", "locked": false, "assignee": null, "assignees": [], "milestone": null, "comments": 0, "created_at": "2019-03-29T19:08:32Z", "updated_at": "2019-03-29T21:15:27Z", "closed_at": "2019-03-29T21:15:27Z", "author_association": "CONTRIBUTOR", "active_lock_reason": null, "body": "We've identified some potential problems that can happen if any of the non-custom user attributes that are expected to be strings (that is, all of them except `:anonymous`) are instead set to a number or some other type. The Python SDK, like the other SDKs in weakly-typed languages, does not prevent this since the user object is simply a dictionary.\r\n\r\n1. LaunchDarkly will not process analytics events for such a user.\r\n2. If you set `\"secondary\"` to a non-string, and try to evaluate a flag that has a percentage rollout, the evaluation will fail.\r\n\r\nWe believe this behavior is the same in all existing versions of the Python SDK.\r\n\r\nOur planned fix is to make the SDK coerce these values to strings as needed. To avoid causing unexpected changes in behavior for existing code, we will not enforce strict typing in this major version.", "performed_via_github_app": null, "score": 1.0}, {"url": "https://api.github.com/repos/launchdarkly/python-server-sdk/issues/114", "repository_url": "https://api.github.com/repos/launchdarkly/python-server-sdk", "labels_url": "https://api.github.com/repos/launchdarkly/python-server-sdk/issues/114/labels{/name}", "comments_url": "https://api.github.com/repos/launchdarkly/python-server-sdk/issues/114/comments", "events_url": "https://api.github.com/repos/launchdarkly/python-server-sdk/issues/114/events", "html_url": "https://github.com/launchdarkly/python-server-sdk/issues/114", "id": 427026760, "node_id": "MDU6SXNzdWU0MjcwMjY3NjA=", "number": 114, "title": "Support for mobile key", "user": {"login": "radj", "id": 466972, "node_id": "MDQ6VXNlcjQ2Njk3Mg==", "avatar_url": "https://avatars3.githubusercontent.com/u/466972?v=4", "gravatar_id": "", "url": "https://api.github.com/users/radj", "html_url": "https://github.com/radj", "followers_url": "https://api.github.com/users/radj/followers", "following_url": "https://api.github.com/users/radj/following{/other_user}", "gists_url": "https://api.github.com/users/radj/gists{/gist_id}", "starred_url": "https://api.github.com/users/radj/starred{/owner}{/repo}", "subscriptions_url": "https://api.github.com/users/radj/subscriptions", "organizations_url": "https://api.github.com/users/radj/orgs", "repos_url": "https://api.github.com/users/radj/repos", "events_url": "https://api.github.com/users/radj/events{/privacy}", "received_events_url": "https://api.github.com/users/radj/received_events", "type": "User", "site_admin": false}, "labels": [], "state": "closed", "locked": false, "assignee": null, "assignees": [], "milestone": null, "comments": 3, "created_at": "2019-03-29T14:54:21Z", "updated_at": "2019-03-30T03:48:34Z", "closed_at": "2019-03-30T03:48:34Z", "author_association": "NONE", "active_lock_reason": null, "body": "**Is your feature request related to a problem? Please describe.**\r\nI would like to have support of mobile key in the Python SDK.\r\n\r\n**Describe the solution you'd like**\r\nThe Python SDK can reach access the LD server using the mobile key for client side Python scripts.\r\n\r\n**Describe alternatives you've considered**\r\nCreating another project to dump \"unsecure\" flags in and use the SDK key of this project. If ever the key is compromised, they only see the \"unsecure\" flags.\r\n\r\n**Additional context**\r\nI tried using mobile key with Python SDK but initialization fails.\r\n", "performed_via_github_app": null, "score": 1.0}, {"url": "https://api.github.com/repos/launchdarkly/python-server-sdk/issues/110", "repository_url": "https://api.github.com/repos/launchdarkly/python-server-sdk", "labels_url": "https://api.github.com/repos/launchdarkly/python-server-sdk/issues/110/labels{/name}", "comments_url": "https://api.github.com/repos/launchdarkly/python-server-sdk/issues/110/comments", "events_url": "https://api.github.com/repos/launchdarkly/python-server-sdk/issues/110/events", "html_url": "https://github.com/launchdarkly/python-server-sdk/issues/110", "id": 409034669, "node_id": "MDU6SXNzdWU0MDkwMzQ2Njk=", "number": 110, "title": "Generated documentation for Python SDK", "user": {"login": "eli-darkly", "id": 35503443, "node_id": "MDQ6VXNlcjM1NTAzNDQz", "avatar_url": "https://avatars0.githubusercontent.com/u/35503443?v=4", "gravatar_id": "", "url": "https://api.github.com/users/eli-darkly", "html_url": "https://github.com/eli-darkly", "followers_url": "https://api.github.com/users/eli-darkly/followers", "following_url": "https://api.github.com/users/eli-darkly/following{/other_user}", "gists_url": "https://api.github.com/users/eli-darkly/gists{/gist_id}", "starred_url": "https://api.github.com/users/eli-darkly/starred{/owner}{/repo}", "subscriptions_url": "https://api.github.com/users/eli-darkly/subscriptions", "organizations_url": "https://api.github.com/users/eli-darkly/orgs", "repos_url": "https://api.github.com/users/eli-darkly/repos", "events_url": "https://api.github.com/users/eli-darkly/events{/privacy}", "received_events_url": "https://api.github.com/users/eli-darkly/received_events", "type": "User", "site_admin": false}, "labels": [], "state": "closed", "locked": false, "assignee": null, "assignees": [], "milestone": null, "comments": 1, "created_at": "2019-02-11T23:53:28Z", "updated_at": "2019-02-13T02:29:10Z", "closed_at": "2019-02-13T02:29:10Z", "author_association": "CONTRIBUTOR", "active_lock_reason": null, "body": "Although the SDK contains documentation comments in Sphinx format, they weren't viewable anywhere except in your IDE. We will be putting them online starting with the next release, and maintaining them for every release version after that. We've also done some editing to improve the completeness and correctness of these comments.\r\n\r\nIf you'd like to watch this issue, we will update it when the docs go online.", "performed_via_github_app": null, "score": 1.0}, {"url": "https://api.github.com/repos/launchdarkly/python-server-sdk/issues/109", "repository_url": "https://api.github.com/repos/launchdarkly/python-server-sdk", "labels_url": "https://api.github.com/repos/launchdarkly/python-server-sdk/issues/109/labels{/name}", "comments_url": "https://api.github.com/repos/launchdarkly/python-server-sdk/issues/109/comments", "events_url": "https://api.github.com/repos/launchdarkly/python-server-sdk/issues/109/events", "html_url": "https://github.com/launchdarkly/python-server-sdk/issues/109", "id": 408496404, "node_id": "MDU6SXNzdWU0MDg0OTY0MDQ=", "number": 109, "title": "Can jsonpickle's version restriction be relaxed? (0.9.3 -> 0.9.6)", "user": {"login": "phobologic", "id": 517334, "node_id": "MDQ6VXNlcjUxNzMzNA==", "avatar_url": "https://avatars2.githubusercontent.com/u/517334?v=4", "gravatar_id": "", "url": "https://api.github.com/users/phobologic", "html_url": "https://github.com/phobologic", "followers_url": "https://api.github.com/users/phobologic/followers", "following_url": "https://api.github.com/users/phobologic/following{/other_user}", "gists_url": "https://api.github.com/users/phobologic/gists{/gist_id}", "starred_url": "https://api.github.com/users/phobologic/starred{/owner}{/repo}", "subscriptions_url": "https://api.github.com/users/phobologic/subscriptions", "organizations_url": "https://api.github.com/users/phobologic/orgs", "repos_url": "https://api.github.com/users/phobologic/repos", "events_url": "https://api.github.com/users/phobologic/events{/privacy}", "received_events_url": "https://api.github.com/users/phobologic/received_events", "type": "User", "site_admin": false}, "labels": [], "state": "closed", "locked": false, "assignee": null, "assignees": [], "milestone": null, "comments": 2, "created_at": "2019-02-10T03:27:39Z", "updated_at": "2019-02-13T02:28:40Z", "closed_at": "2019-02-13T02:28:40Z", "author_association": "NONE", "active_lock_reason": null, "body": "Hi, I'm trying to make use of launchdarkly in my app, but I'm having issues because of the fact that we also use jsonpickle in it, and we're using it at version 0.9.6.  I was wondering if there was anything stopping this library from updating to <1.0.0?  1.0 they got rid of python 3.3 support (since it EOLd), so I understand if you can't upgrade there, but 0.9.6 should be version safe/compatible, and even adds some new features/clears up some old bugs.\r\n\r\nThanks!", "performed_via_github_app": null, "score": 1.0}, {"url": "https://api.github.com/repos/launchdarkly/python-server-sdk/issues/105", "repository_url": "https://api.github.com/repos/launchdarkly/python-server-sdk", "labels_url": "https://api.github.com/repos/launchdarkly/python-server-sdk/issues/105/labels{/name}", "comments_url": "https://api.github.com/repos/launchdarkly/python-server-sdk/issues/105/comments", "events_url": "https://api.github.com/repos/launchdarkly/python-server-sdk/issues/105/events", "html_url": "https://github.com/launchdarkly/python-server-sdk/issues/105", "id": 405392739, "node_id": "MDU6SXNzdWU0MDUzOTI3Mzk=", "number": 105, "title": "Packaging error in v6.8.0 and 6.8.1", "user": {"login": "eli-darkly", "id": 35503443, "node_id": "MDQ6VXNlcjM1NTAzNDQz", "avatar_url": "https://avatars0.githubusercontent.com/u/35503443?v=4", "gravatar_id": "", "url": "https://api.github.com/users/eli-darkly", "html_url": "https://github.com/eli-darkly", "followers_url": "https://api.github.com/users/eli-darkly/followers", "following_url": "https://api.github.com/users/eli-darkly/following{/other_user}", "gists_url": "https://api.github.com/users/eli-darkly/gists{/gist_id}", "starred_url": "https://api.github.com/users/eli-darkly/starred{/owner}{/repo}", "subscriptions_url": "https://api.github.com/users/eli-darkly/subscriptions", "organizations_url": "https://api.github.com/users/eli-darkly/orgs", "repos_url": "https://api.github.com/users/eli-darkly/repos", "events_url": "https://api.github.com/users/eli-darkly/events{/privacy}", "received_events_url": "https://api.github.com/users/eli-darkly/received_events", "type": "User", "site_admin": false}, "labels": [], "state": "closed", "locked": false, "assignee": null, "assignees": [], "milestone": null, "comments": 3, "created_at": "2019-01-31T19:04:33Z", "updated_at": "2019-01-31T23:56:30Z", "closed_at": "2019-01-31T23:56:30Z", "author_association": "CONTRIBUTOR", "active_lock_reason": null, "body": "An error in package metadata has made it impossible to install the 6.8.0 release. We'll have a patch out shortly, and we'll be adding a test of the full packaging/installation process to our CI test suite. Sorry about that.", "performed_via_github_app": null, "score": 1.0}, {"url": "https://api.github.com/repos/launchdarkly/python-server-sdk/issues/102", "repository_url": "https://api.github.com/repos/launchdarkly/python-server-sdk", "labels_url": "https://api.github.com/repos/launchdarkly/python-server-sdk/issues/102/labels{/name}", "comments_url": "https://api.github.com/repos/launchdarkly/python-server-sdk/issues/102/comments", "events_url": "https://api.github.com/repos/launchdarkly/python-server-sdk/issues/102/events", "html_url": "https://github.com/launchdarkly/python-server-sdk/issues/102", "id": 399361776, "node_id": "MDU6SXNzdWUzOTkzNjE3NzY=", "number": 102, "title": "DynamoDB feature store support", "user": {"login": "Vlaaaaaaad", "id": 5440007, "node_id": "MDQ6VXNlcjU0NDAwMDc=", "avatar_url": "https://avatars3.githubusercontent.com/u/5440007?v=4", "gravatar_id": "", "url": "https://api.github.com/users/Vlaaaaaaad", "html_url": "https://github.com/Vlaaaaaaad", "followers_url": "https://api.github.com/users/Vlaaaaaaad/followers", "following_url": "https://api.github.com/users/Vlaaaaaaad/following{/other_user}", "gists_url": "https://api.github.com/users/Vlaaaaaaad/gists{/gist_id}", "starred_url": "https://api.github.com/users/Vlaaaaaaad/starred{/owner}{/repo}", "subscriptions_url": "https://api.github.com/users/Vlaaaaaaad/subscriptions", "organizations_url": "https://api.github.com/users/Vlaaaaaaad/orgs", "repos_url": "https://api.github.com/users/Vlaaaaaaad/repos", "events_url": "https://api.github.com/users/Vlaaaaaaad/events{/privacy}", "received_events_url": "https://api.github.com/users/Vlaaaaaaad/received_events", "type": "User", "site_admin": false}, "labels": [], "state": "closed", "locked": false, "assignee": null, "assignees": [], "milestone": null, "comments": 2, "created_at": "2019-01-15T14:10:06Z", "updated_at": "2019-01-16T02:01:41Z", "closed_at": "2019-01-16T02:01:41Z", "author_association": "NONE", "active_lock_reason": null, "body": "For serverless usecases [DynamoDB was implemented as a feature store state in the Go, Java, .NET and Node SDKs](\r\nhttps://docs.launchdarkly.com/v2.0/docs/using-a-persistent-feature-store#section-using-dynamodb).\r\n\r\nCreating this issue to express interest in supporting DynamoDB feature store in the Python SDK too.", "performed_via_github_app": null, "score": 1.0}, {"url": "https://api.github.com/repos/launchdarkly/python-server-sdk/issues/92", "repository_url": "https://api.github.com/repos/launchdarkly/python-server-sdk", "labels_url": "https://api.github.com/repos/launchdarkly/python-server-sdk/issues/92/labels{/name}", "comments_url": "https://api.github.com/repos/launchdarkly/python-server-sdk/issues/92/comments", "events_url": "https://api.github.com/repos/launchdarkly/python-server-sdk/issues/92/events", "html_url": "https://github.com/launchdarkly/python-server-sdk/issues/92", "id": 336719809, "node_id": "MDU6SXNzdWUzMzY3MTk4MDk=", "number": 92, "title": "Add Support for Python 3.7", "user": {"login": "levlaz", "id": 7981032, "node_id": "MDQ6VXNlcjc5ODEwMzI=", "avatar_url": "https://avatars2.githubusercontent.com/u/7981032?v=4", "gravatar_id": "", "url": "https://api.github.com/users/levlaz", "html_url": "https://github.com/levlaz", "followers_url": "https://api.github.com/users/levlaz/followers", "following_url": "https://api.github.com/users/levlaz/following{/other_user}", "gists_url": "https://api.github.com/users/levlaz/gists{/gist_id}", "starred_url": "https://api.github.com/users/levlaz/starred{/owner}{/repo}", "subscriptions_url": "https://api.github.com/users/levlaz/subscriptions", "organizations_url": "https://api.github.com/users/levlaz/orgs", "repos_url": "https://api.github.com/users/levlaz/repos", "events_url": "https://api.github.com/users/levlaz/events{/privacy}", "received_events_url": "https://api.github.com/users/levlaz/received_events", "type": "User", "site_admin": false}, "labels": [], "state": "closed", "locked": false, "assignee": null, "assignees": [], "milestone": null, "comments": 2, "created_at": "2018-06-28T17:53:57Z", "updated_at": "2018-07-05T17:49:56Z", "closed_at": "2018-07-05T17:49:56Z", "author_association": "MEMBER", "active_lock_reason": null, "body": "[Python 3.7](https://www.python.org/downloads/release/python-370/) was released yesterday. As folks start moving over to this version it would be nice to stay ahead of things and add proper support. ", "performed_via_github_app": null, "score": 1.0}, {"url": "https://api.github.com/repos/launchdarkly/python-server-sdk/issues/88", "repository_url": "https://api.github.com/repos/launchdarkly/python-server-sdk", "labels_url": "https://api.github.com/repos/launchdarkly/python-server-sdk/issues/88/labels{/name}", "comments_url": "https://api.github.com/repos/launchdarkly/python-server-sdk/issues/88/comments", "events_url": "https://api.github.com/repos/launchdarkly/python-server-sdk/issues/88/events", "html_url": "https://github.com/launchdarkly/python-server-sdk/issues/88", "id": 328361981, "node_id": "MDU6SXNzdWUzMjgzNjE5ODE=", "number": 88, "title": "Backing off log.error() causes multiple issues on Sentry", "user": {"login": "henryl", "id": 140025, "node_id": "MDQ6VXNlcjE0MDAyNQ==", "avatar_url": "https://avatars2.githubusercontent.com/u/140025?v=4", "gravatar_id": "", "url": "https://api.github.com/users/henryl", "html_url": "https://github.com/henryl", "followers_url": "https://api.github.com/users/henryl/followers", "following_url": "https://api.github.com/users/henryl/following{/other_user}", "gists_url": "https://api.github.com/users/henryl/gists{/gist_id}", "starred_url": "https://api.github.com/users/henryl/starred{/owner}{/repo}", "subscriptions_url": "https://api.github.com/users/henryl/subscriptions", "organizations_url": "https://api.github.com/users/henryl/orgs", "repos_url": "https://api.github.com/users/henryl/repos", "events_url": "https://api.github.com/users/henryl/events{/privacy}", "received_events_url": "https://api.github.com/users/henryl/received_events", "type": "User", "site_admin": false}, "labels": [], "state": "closed", "locked": false, "assignee": null, "assignees": [], "milestone": null, "comments": 6, "created_at": "2018-06-01T02:49:01Z", "updated_at": "2018-10-09T18:36:37Z", "closed_at": "2018-10-09T18:36:37Z", "author_association": "NONE", "active_lock_reason": null, "body": "Like many people, we use Sentry for exception logging. The `backoff` library you guys are using will log messages that look like:\r\n\r\n```\r\nBacking off _connect(...) for 0.7s (requests.exceptions.ReadTimeout: HTTPSConnectionPool(host='st...\r\nBacking off _connect(...) for 1.0s (requests.exceptions.ReadTimeout: HTTPSConnectionPool(host='st...\r\n...\r\n```\r\n\r\nEach of these log messages counts as separate issue. On a recent LD outage, we had thousands of these issues and events inside of Sentry, which was really annoying.", "performed_via_github_app": null, "score": 1.0}, {"url": "https://api.github.com/repos/launchdarkly/python-server-sdk/issues/86", "repository_url": "https://api.github.com/repos/launchdarkly/python-server-sdk", "labels_url": "https://api.github.com/repos/launchdarkly/python-server-sdk/issues/86/labels{/name}", "comments_url": "https://api.github.com/repos/launchdarkly/python-server-sdk/issues/86/comments", "events_url": "https://api.github.com/repos/launchdarkly/python-server-sdk/issues/86/events", "html_url": "https://github.com/launchdarkly/python-server-sdk/issues/86", "id": 327294066, "node_id": "MDU6SXNzdWUzMjcyOTQwNjY=", "number": 86, "title": "ldclient.get() call is getting hanged (time out) on updating requests version to 2.18.4 from 2.12.5", "user": {"login": "akash-gautam", "id": 20444009, "node_id": "MDQ6VXNlcjIwNDQ0MDA5", "avatar_url": "https://avatars2.githubusercontent.com/u/20444009?v=4", "gravatar_id": "", "url": "https://api.github.com/users/akash-gautam", "html_url": "https://github.com/akash-gautam", "followers_url": "https://api.github.com/users/akash-gautam/followers", "following_url": "https://api.github.com/users/akash-gautam/following{/other_user}", "gists_url": "https://api.github.com/users/akash-gautam/gists{/gist_id}", "starred_url": "https://api.github.com/users/akash-gautam/starred{/owner}{/repo}", "subscriptions_url": "https://api.github.com/users/akash-gautam/subscriptions", "organizations_url": "https://api.github.com/users/akash-gautam/orgs", "repos_url": "https://api.github.com/users/akash-gautam/repos", "events_url": "https://api.github.com/users/akash-gautam/events{/privacy}", "received_events_url": "https://api.github.com/users/akash-gautam/received_events", "type": "User", "site_admin": false}, "labels": [], "state": "closed", "locked": false, "assignee": null, "assignees": [], "milestone": null, "comments": 3, "created_at": "2018-05-29T12:14:49Z", "updated_at": "2019-10-31T19:14:39Z", "closed_at": "2019-10-31T19:14:39Z", "author_association": "NONE", "active_lock_reason": null, "body": "Description: The ldclient.get() call is getting timed out in my service on updating the requests version from 2.12.5 to 2.18.4 . On probing further I found out that the ldclient.get() method calls LDClient (in client.py file) and LDClient calls self._update_processor.start() this is the call which is actually getting timed out. If I comment out the self._update_processor.start() call then the ldclient.get() runs fine.  One more thing is that ldclient has a requirement requests>=2.17.3 but still it seems to be working with the lower version. I tried with the updated versions of ldclient as well but got the same behaviour.\r\n\r\nEnv details:\r\nPython: 2.7\r\nLDClient: 5.0.4\r\nRequests: 2.18.4\r\nUbuntu:14.04", "performed_via_github_app": null, "score": 1.0}, {"url": "https://api.github.com/repos/launchdarkly/python-server-sdk/issues/84", "repository_url": "https://api.github.com/repos/launchdarkly/python-server-sdk", "labels_url": "https://api.github.com/repos/launchdarkly/python-server-sdk/issues/84/labels{/name}", "comments_url": "https://api.github.com/repos/launchdarkly/python-server-sdk/issues/84/comments", "events_url": "https://api.github.com/repos/launchdarkly/python-server-sdk/issues/84/events", "html_url": "https://github.com/launchdarkly/python-server-sdk/issues/84", "id": 325403290, "node_id": "MDU6SXNzdWUzMjU0MDMyOTA=", "number": 84, "title": "Inaccurate uwsgi `enable-threads` error logging", "user": {"login": "dougkeen", "id": 1517173, "node_id": "MDQ6VXNlcjE1MTcxNzM=", "avatar_url": "https://avatars1.githubusercontent.com/u/1517173?v=4", "gravatar_id": "", "url": "https://api.github.com/users/dougkeen", "html_url": "https://github.com/dougkeen", "followers_url": "https://api.github.com/users/dougkeen/followers", "following_url": "https://api.github.com/users/dougkeen/following{/other_user}", "gists_url": "https://api.github.com/users/dougkeen/gists{/gist_id}", "starred_url": "https://api.github.com/users/dougkeen/starred{/owner}{/repo}", "subscriptions_url": "https://api.github.com/users/dougkeen/subscriptions", "organizations_url": "https://api.github.com/users/dougkeen/orgs", "repos_url": "https://api.github.com/users/dougkeen/repos", "events_url": "https://api.github.com/users/dougkeen/events{/privacy}", "received_events_url": "https://api.github.com/users/dougkeen/received_events", "type": "User", "site_admin": false}, "labels": [], "state": "closed", "locked": false, "assignee": null, "assignees": [], "milestone": null, "comments": 2, "created_at": "2018-05-22T18:00:42Z", "updated_at": "2018-06-04T20:34:00Z", "closed_at": "2018-06-04T20:34:00Z", "author_association": "NONE", "active_lock_reason": null, "body": "Right now, if you run the client in a uwsgi environment without the `enable-threads` option set, this message gets error logged:\r\n> The LaunchDarkly client requires the enable-threads option be passed to uWSGI.\r\n\r\nHowever, the uwsgi config could _not_ have `enable-threads` explicitly set, but rather have threads [implicitly enabled by setting a `threads` option](http://uwsgi-docs.readthedocs.io/en/latest/ThingsToKnow.html).\r\n> By default the Python plugin does not initialize the GIL. This means your app-generated threads will not run. If you need threads, remember to enable them with enable-threads. Running uWSGI in multithreading mode (with the threads options) will automatically enable threading support. This \u201cstrange\u201d default behaviour is for performance reasons, no shame in that.\r\n\r\nIn the case where `enable-threads` is not specified in the uwsgi config, but `threads` is, the LaunchDarkly client will incorrectly log the above error message.", "performed_via_github_app": null, "score": 1.0}, {"url": "https://api.github.com/repos/launchdarkly/python-server-sdk/issues/80", "repository_url": "https://api.github.com/repos/launchdarkly/python-server-sdk", "labels_url": "https://api.github.com/repos/launchdarkly/python-server-sdk/issues/80/labels{/name}", "comments_url": "https://api.github.com/repos/launchdarkly/python-server-sdk/issues/80/comments", "events_url": "https://api.github.com/repos/launchdarkly/python-server-sdk/issues/80/events", "html_url": "https://github.com/launchdarkly/python-server-sdk/issues/80", "id": 314339413, "node_id": "MDU6SXNzdWUzMTQzMzk0MTM=", "number": 80, "title": "Install broken on pip 10.x", "user": {"login": "mattbriancon", "id": 152974, "node_id": "MDQ6VXNlcjE1Mjk3NA==", "avatar_url": "https://avatars0.githubusercontent.com/u/152974?v=4", "gravatar_id": "", "url": "https://api.github.com/users/mattbriancon", "html_url": "https://github.com/mattbriancon", "followers_url": "https://api.github.com/users/mattbriancon/followers", "following_url": "https://api.github.com/users/mattbriancon/following{/other_user}", "gists_url": "https://api.github.com/users/mattbriancon/gists{/gist_id}", "starred_url": "https://api.github.com/users/mattbriancon/starred{/owner}{/repo}", "subscriptions_url": "https://api.github.com/users/mattbriancon/subscriptions", "organizations_url": "https://api.github.com/users/mattbriancon/orgs", "repos_url": "https://api.github.com/users/mattbriancon/repos", "events_url": "https://api.github.com/users/mattbriancon/events{/privacy}", "received_events_url": "https://api.github.com/users/mattbriancon/received_events", "type": "User", "site_admin": false}, "labels": [], "state": "closed", "locked": false, "assignee": null, "assignees": [], "milestone": null, "comments": 8, "created_at": "2018-04-14T15:52:52Z", "updated_at": "2018-04-16T18:05:05Z", "closed_at": "2018-04-16T17:53:23Z", "author_association": "CONTRIBUTOR", "active_lock_reason": null, "body": "From the [pip CHANGELOG](https://pip.pypa.io/en/stable/news/#b1-2018-03-31):\r\n\r\n> Move all of pip's APIs into the pip._internal package, properly reflecting the fact that pip does not currently have any public APIs. (#4696, #4700)\r\n\r\n```\r\nCollecting ldclient-py==4.0.6 (from -r requirements.txt (line 74))\r\n  Downloading ldclient-py-4.0.6.tar.gz\r\n    Complete output from command python setup.py egg_info:\r\n    Traceback (most recent call last):\r\n      File \"<string>\", line 1, in <module>\r\n      File \"/tmp/pip-install-qsq8HS/ldclient-py/setup.py\", line 9, in <module>\r\n        from pip.req import parse_requirements\r\n    ImportError: No module named req\r\n\r\n    ----------------------------------------\r\nCommand \"python setup.py egg_info\" failed with error code 1 in /tmp/pip-install-qsq8HS/ldclient-py/\r\n```", "performed_via_github_app": null, "score": 1.0}, {"url": "https://api.github.com/repos/launchdarkly/python-server-sdk/issues/75", "repository_url": "https://api.github.com/repos/launchdarkly/python-server-sdk", "labels_url": "https://api.github.com/repos/launchdarkly/python-server-sdk/issues/75/labels{/name}", "comments_url": "https://api.github.com/repos/launchdarkly/python-server-sdk/issues/75/comments", "events_url": "https://api.github.com/repos/launchdarkly/python-server-sdk/issues/75/events", "html_url": "https://github.com/launchdarkly/python-server-sdk/issues/75", "id": 286323795, "node_id": "MDU6SXNzdWUyODYzMjM3OTU=", "number": 75, "title": "How to Connect using ProxyHost?", "user": {"login": "yks0000", "id": 6111679, "node_id": "MDQ6VXNlcjYxMTE2Nzk=", "avatar_url": "https://avatars0.githubusercontent.com/u/6111679?v=4", "gravatar_id": "", "url": "https://api.github.com/users/yks0000", "html_url": "https://github.com/yks0000", "followers_url": "https://api.github.com/users/yks0000/followers", "following_url": "https://api.github.com/users/yks0000/following{/other_user}", "gists_url": "https://api.github.com/users/yks0000/gists{/gist_id}", "starred_url": "https://api.github.com/users/yks0000/starred{/owner}{/repo}", "subscriptions_url": "https://api.github.com/users/yks0000/subscriptions", "organizations_url": "https://api.github.com/users/yks0000/orgs", "repos_url": "https://api.github.com/users/yks0000/repos", "events_url": "https://api.github.com/users/yks0000/events{/privacy}", "received_events_url": "https://api.github.com/users/yks0000/received_events", "type": "User", "site_admin": false}, "labels": [], "state": "closed", "locked": false, "assignee": null, "assignees": [], "milestone": null, "comments": 1, "created_at": "2018-01-05T15:42:58Z", "updated_at": "2018-01-05T15:55:34Z", "closed_at": "2018-01-05T15:55:34Z", "author_association": "NONE", "active_lock_reason": null, "body": "We are not seeing any reference in Python-SDK to connect via Proxy Host. Could you please suggest?", "performed_via_github_app": null, "score": 1.0}, {"url": "https://api.github.com/repos/launchdarkly/python-server-sdk/issues/73", "repository_url": "https://api.github.com/repos/launchdarkly/python-server-sdk", "labels_url": "https://api.github.com/repos/launchdarkly/python-server-sdk/issues/73/labels{/name}", "comments_url": "https://api.github.com/repos/launchdarkly/python-server-sdk/issues/73/comments", "events_url": "https://api.github.com/repos/launchdarkly/python-server-sdk/issues/73/events", "html_url": "https://github.com/launchdarkly/python-server-sdk/issues/73", "id": 256823499, "node_id": "MDU6SXNzdWUyNTY4MjM0OTk=", "number": 73, "title": "4.0.6 tagged as 2.0.6", "user": {"login": "ryanwilsonperkin", "id": 3004111, "node_id": "MDQ6VXNlcjMwMDQxMTE=", "avatar_url": "https://avatars1.githubusercontent.com/u/3004111?v=4", "gravatar_id": "", "url": "https://api.github.com/users/ryanwilsonperkin", "html_url": "https://github.com/ryanwilsonperkin", "followers_url": "https://api.github.com/users/ryanwilsonperkin/followers", "following_url": "https://api.github.com/users/ryanwilsonperkin/following{/other_user}", "gists_url": "https://api.github.com/users/ryanwilsonperkin/gists{/gist_id}", "starred_url": "https://api.github.com/users/ryanwilsonperkin/starred{/owner}{/repo}", "subscriptions_url": "https://api.github.com/users/ryanwilsonperkin/subscriptions", "organizations_url": "https://api.github.com/users/ryanwilsonperkin/orgs", "repos_url": "https://api.github.com/users/ryanwilsonperkin/repos", "events_url": "https://api.github.com/users/ryanwilsonperkin/events{/privacy}", "received_events_url": "https://api.github.com/users/ryanwilsonperkin/received_events", "type": "User", "site_admin": false}, "labels": [], "state": "closed", "locked": false, "assignee": null, "assignees": [], "milestone": null, "comments": 1, "created_at": "2017-09-11T19:57:34Z", "updated_at": "2017-09-11T21:27:06Z", "closed_at": "2017-09-11T21:27:06Z", "author_association": "NONE", "active_lock_reason": null, "body": "Hey folks, just bringing it to your attention that it appears v4.0.6. has been mis-tagged as 2.0.6 on GitHub releases: https://github.com/launchdarkly/python-client/tags", "performed_via_github_app": null, "score": 1.0}, {"url": "https://api.github.com/repos/launchdarkly/python-server-sdk/issues/71", "repository_url": "https://api.github.com/repos/launchdarkly/python-server-sdk", "labels_url": "https://api.github.com/repos/launchdarkly/python-server-sdk/issues/71/labels{/name}", "comments_url": "https://api.github.com/repos/launchdarkly/python-server-sdk/issues/71/comments", "events_url": "https://api.github.com/repos/launchdarkly/python-server-sdk/issues/71/events", "html_url": "https://github.com/launchdarkly/python-server-sdk/issues/71", "id": 225509202, "node_id": "MDU6SXNzdWUyMjU1MDkyMDI=", "number": 71, "title": "a GAE-friendly (probably synchronous) client?", "user": {"login": "jcjones1515", "id": 6596226, "node_id": "MDQ6VXNlcjY1OTYyMjY=", "avatar_url": "https://avatars2.githubusercontent.com/u/6596226?v=4", "gravatar_id": "", "url": "https://api.github.com/users/jcjones1515", "html_url": "https://github.com/jcjones1515", "followers_url": "https://api.github.com/users/jcjones1515/followers", "following_url": "https://api.github.com/users/jcjones1515/following{/other_user}", "gists_url": "https://api.github.com/users/jcjones1515/gists{/gist_id}", "starred_url": "https://api.github.com/users/jcjones1515/starred{/owner}{/repo}", "subscriptions_url": "https://api.github.com/users/jcjones1515/subscriptions", "organizations_url": "https://api.github.com/users/jcjones1515/orgs", "repos_url": "https://api.github.com/users/jcjones1515/repos", "events_url": "https://api.github.com/users/jcjones1515/events{/privacy}", "received_events_url": "https://api.github.com/users/jcjones1515/received_events", "type": "User", "site_admin": false}, "labels": [], "state": "closed", "locked": false, "assignee": null, "assignees": [], "milestone": null, "comments": 6, "created_at": "2017-05-01T19:45:51Z", "updated_at": "2018-10-09T18:37:33Z", "closed_at": "2018-10-09T18:37:33Z", "author_association": "NONE", "active_lock_reason": null, "body": "I'm evaluating LaunchDarkly for my company and I'm running into some issues getting things going on Google App Engine standard for python.\r\n\r\nI got past the [familiar SSL issues](https://cloud.google.com/appengine/docs/standard/python/issue-requests), but App Engine Standard and background threads aren't very compatible, I was wondering if there was a simple way to make the client be synchronous with perhaps some in-memory caching.  I'd be more than willing to contribute code along these lines but would need some guidance.\r\n\r\nI found a [similar issue](https://github.com/segmentio/analytics-python/issues/34) with a different library that seems to have found a workaround.\r\n\r\nThanks,\r\n\r\nJason", "performed_via_github_app": null, "score": 1.0}, {"url": "https://api.github.com/repos/launchdarkly/python-server-sdk/issues/70", "repository_url": "https://api.github.com/repos/launchdarkly/python-server-sdk", "labels_url": "https://api.github.com/repos/launchdarkly/python-server-sdk/issues/70/labels{/name}", "comments_url": "https://api.github.com/repos/launchdarkly/python-server-sdk/issues/70/comments", "events_url": "https://api.github.com/repos/launchdarkly/python-server-sdk/issues/70/events", "html_url": "https://github.com/launchdarkly/python-server-sdk/issues/70", "id": 224287472, "node_id": "MDU6SXNzdWUyMjQyODc0NzI=", "number": 70, "title": "'matches' operator is anchored to the beginning of the string", "user": {"login": "pkaeding", "id": 13951, "node_id": "MDQ6VXNlcjEzOTUx", "avatar_url": "https://avatars2.githubusercontent.com/u/13951?v=4", "gravatar_id": "", "url": "https://api.github.com/users/pkaeding", "html_url": "https://github.com/pkaeding", "followers_url": "https://api.github.com/users/pkaeding/followers", "following_url": "https://api.github.com/users/pkaeding/following{/other_user}", "gists_url": "https://api.github.com/users/pkaeding/gists{/gist_id}", "starred_url": "https://api.github.com/users/pkaeding/starred{/owner}{/repo}", "subscriptions_url": "https://api.github.com/users/pkaeding/subscriptions", "organizations_url": "https://api.github.com/users/pkaeding/orgs", "repos_url": "https://api.github.com/users/pkaeding/repos", "events_url": "https://api.github.com/users/pkaeding/events{/privacy}", "received_events_url": "https://api.github.com/users/pkaeding/received_events", "type": "User", "site_admin": false}, "labels": [], "state": "closed", "locked": false, "assignee": null, "assignees": [], "milestone": null, "comments": 1, "created_at": "2017-04-25T22:12:03Z", "updated_at": "2017-04-25T23:28:05Z", "closed_at": "2017-04-25T23:28:05Z", "author_association": "CONTRIBUTOR", "active_lock_reason": null, "body": "Given a user like this:\r\n\r\n```\r\n{\r\n  'key': 'user-key',\r\n  'custom': {\r\n    'greeting': 'hello world',\r\n  }\r\n}\r\n```\r\n\r\nAnd a flag target using the 'matches' operator with a regex that should match a part of the value: `(world|planet)`\r\n\r\n![](https://dl.dropboxusercontent.com/s/ssduey2iw1on9qi/2017-04-25%20at%203.11%20PM%20%281%29.png?dl=0)\r\n\r\nThe user should match the targeting rule, but does not. In other LaunchDarkly SDKs, the user does match this rule.\r\n", "performed_via_github_app": null, "score": 1.0}, {"url": "https://api.github.com/repos/launchdarkly/python-server-sdk/issues/69", "repository_url": "https://api.github.com/repos/launchdarkly/python-server-sdk", "labels_url": "https://api.github.com/repos/launchdarkly/python-server-sdk/issues/69/labels{/name}", "comments_url": "https://api.github.com/repos/launchdarkly/python-server-sdk/issues/69/comments", "events_url": "https://api.github.com/repos/launchdarkly/python-server-sdk/issues/69/events", "html_url": "https://github.com/launchdarkly/python-server-sdk/issues/69", "id": 214218764, "node_id": "MDU6SXNzdWUyMTQyMTg3NjQ=", "number": 69, "title": "Problem importing lib v4.0.2", "user": {"login": "nelz9999", "id": 10950, "node_id": "MDQ6VXNlcjEwOTUw", "avatar_url": "https://avatars1.githubusercontent.com/u/10950?v=4", "gravatar_id": "", "url": "https://api.github.com/users/nelz9999", "html_url": "https://github.com/nelz9999", "followers_url": "https://api.github.com/users/nelz9999/followers", "following_url": "https://api.github.com/users/nelz9999/following{/other_user}", "gists_url": "https://api.github.com/users/nelz9999/gists{/gist_id}", "starred_url": "https://api.github.com/users/nelz9999/starred{/owner}{/repo}", "subscriptions_url": "https://api.github.com/users/nelz9999/subscriptions", "organizations_url": "https://api.github.com/users/nelz9999/orgs", "repos_url": "https://api.github.com/users/nelz9999/repos", "events_url": "https://api.github.com/users/nelz9999/events{/privacy}", "received_events_url": "https://api.github.com/users/nelz9999/received_events", "type": "User", "site_admin": false}, "labels": [], "state": "closed", "locked": false, "assignee": null, "assignees": [], "milestone": null, "comments": 3, "created_at": "2017-03-14T21:56:19Z", "updated_at": "2017-03-14T22:11:25Z", "closed_at": "2017-03-14T22:11:24Z", "author_association": "NONE", "active_lock_reason": null, "body": "Looks like maybe `python2.6-requirements.txt` isn't in the zip file on PYPI.\r\n\r\n```\r\nSearching for ldclient-py>=4.0.0\r\nReading https://pypi.python.org/simple/ldclient-py/\r\nDownloading https://pypi.python.org/packages/4a/19/744c4fa7ab4116b3267de1ec132290b92fb4c24e39de0cb421aee6ae4fab/ldclient-py-4.0.2.tar.gz#md5=781fdd286c422f31155364c30c188ae0\r\nBest match: ldclient-py 4.0.2\r\nProcessing ldclient-py-4.0.2.tar.gz\r\nWriting /tmp/easy_install-RZ8Mp3/ldclient-py-4.0.2/setup.cfg\r\nRunning ldclient-py-4.0.2/setup.py -q bdist_egg --dist-dir /tmp/easy_install-RZ8Mp3/ldclient-py-4.0.2/egg-dist-tmp-bLgInv\r\nTraceback (most recent call last):\r\n  File \"setup.py\", line 86, in <module>\r\n    include_package_data=True)\r\n  File \"/opt/circleci/python/2.7.12/lib/python2.7/distutils/core.py\", line 151, in setup\r\n    dist.run_commands()\r\n  File \"/opt/circleci/python/2.7.12/lib/python2.7/distutils/dist.py\", line 953, in run_commands\r\n    self.run_command(cmd)\r\n  File \"/opt/circleci/python/2.7.12/lib/python2.7/distutils/dist.py\", line 972, in run_command\r\n    cmd_obj.run()\r\n  File \"/home/ubuntu/observer/venv/lib/python2.7/site-packages/setuptools/command/install.py\", line 67, in run\r\n    self.do_egg_install()\r\n  File \"/home/ubuntu/observer/venv/lib/python2.7/site-packages/setuptools/command/install.py\", line 117, in do_egg_install\r\n    cmd.run()\r\n  File \"/home/ubuntu/observer/venv/lib/python2.7/site-packages/setuptools/command/easy_install.py\", line 411, in run\r\n    self.easy_install(spec, not self.no_deps)\r\n  File \"/home/ubuntu/observer/venv/lib/python2.7/site-packages/setuptools/command/easy_install.py\", line 655, in easy_install\r\n    return self.install_item(None, spec, tmpdir, deps, True)\r\n  File \"/home/ubuntu/observer/venv/lib/python2.7/site-packages/setuptools/command/easy_install.py\", line 702, in install_item\r\n    self.process_distribution(spec, dist, deps)\r\n  File \"/home/ubuntu/observer/venv/lib/python2.7/site-packages/setuptools/command/easy_install.py\", line 747, in process_distribution\r\n    [requirement], self.local_index, self.easy_install\r\n  File \"/home/ubuntu/observer/venv/lib/python2.7/site-packages/pkg_resources/__init__.py\", line 851, in resolve\r\n    dist = best[req.key] = env.best_match(req, ws, installer)\r\n  File \"/home/ubuntu/observer/venv/lib/python2.7/site-packages/pkg_resources/__init__.py\", line 1123, in best_match\r\n    return self.obtain(req, installer)\r\n  File \"/home/ubuntu/observer/venv/lib/python2.7/site-packages/pkg_resources/__init__.py\", line 1135, in obtain\r\n    return installer(requirement)\r\n  File \"/home/ubuntu/observer/venv/lib/python2.7/site-packages/setuptools/command/easy_install.py\", line 674, in easy_install\r\n    return self.install_item(spec, dist.location, tmpdir, deps)\r\n  File \"/home/ubuntu/observer/venv/lib/python2.7/site-packages/setuptools/command/easy_install.py\", line 700, in install_item\r\n    dists = self.install_eggs(spec, download, tmpdir)\r\n  File \"/home/ubuntu/observer/venv/lib/python2.7/site-packages/setuptools/command/easy_install.py\", line 881, in install_eggs\r\n    return self.build_and_install(setup_script, setup_base)\r\n  File \"/home/ubuntu/observer/venv/lib/python2.7/site-packages/setuptools/command/easy_install.py\", line 1120, in build_and_install\r\n    self.run_setup(setup_script, setup_base, args)\r\n  File \"/home/ubuntu/observer/venv/lib/python2.7/site-packages/setuptools/command/easy_install.py\", line 1106, in run_setup\r\n    run_setup(setup_script, args)\r\n  File \"/home/ubuntu/observer/venv/lib/python2.7/site-packages/setuptools/sandbox.py\", line 258, in run_setup\r\n    raise\r\n  File \"/opt/circleci/python/2.7.12/lib/python2.7/contextlib.py\", line 35, in __exit__\r\n    self.gen.throw(type, value, traceback)\r\n  File \"/home/ubuntu/observer/venv/lib/python2.7/site-packages/setuptools/sandbox.py\", line 198, in setup_context\r\n    yield\r\n  File \"/opt/circleci/python/2.7.12/lib/python2.7/contextlib.py\", line 35, in __exit__\r\n    self.gen.throw(type, value, traceback)\r\n  File \"/home/ubuntu/observer/venv/lib/python2.7/site-packages/setuptools/sandbox.py\", line 169, in save_modules\r\n    saved_exc.resume()\r\n  File \"/home/ubuntu/observer/venv/lib/python2.7/site-packages/setuptools/sandbox.py\", line 144, in resume\r\n    six.reraise(type, exc, self._tb)\r\n  File \"/home/ubuntu/observer/venv/lib/python2.7/site-packages/setuptools/sandbox.py\", line 157, in save_modules\r\n    yield saved\r\n  File \"/home/ubuntu/observer/venv/lib/python2.7/site-packages/setuptools/sandbox.py\", line 198, in setup_context\r\n    yield\r\n  File \"/home/ubuntu/observer/venv/lib/python2.7/site-packages/setuptools/sandbox.py\", line 255, in run_setup\r\n    DirectorySandbox(setup_dir).run(runner)\r\n  File \"/home/ubuntu/observer/venv/lib/python2.7/site-packages/setuptools/sandbox.py\", line 285, in run\r\n    return func()\r\n  File \"/home/ubuntu/observer/venv/lib/python2.7/site-packages/setuptools/sandbox.py\", line 253, in runner\r\n    _execfile(setup_script, ns)\r\n  File \"/home/ubuntu/observer/venv/lib/python2.7/site-packages/setuptools/sandbox.py\", line 47, in _execfile\r\n    exec(code, globals, locals)\r\n  File \"/tmp/easy_install-RZ8Mp3/ldclient-py-4.0.2/setup.py\", line 22, in <module>\r\n    cmd = ['git', 'describe']\r\n  File \"/home/ubuntu/observer/venv/lib/python2.7/site-packages/pip/req/req_file.py\", line 84, in parse_requirements\r\n    filename, comes_from=comes_from, session=session\r\n  File \"/home/ubuntu/observer/venv/lib/python2.7/site-packages/pip/download.py\", line 425, in get_file_content\r\n    'Could not open requirements file: %s' % str(exc)\r\npip.exceptions.InstallationError: Could not open requirements file: [Errno 2] No such file or directory: 'python2.6-requirements.txt'\r\n\r\n```", "performed_via_github_app": null, "score": 1.0}, {"url": "https://api.github.com/repos/launchdarkly/python-server-sdk/issues/67", "repository_url": "https://api.github.com/repos/launchdarkly/python-server-sdk", "labels_url": "https://api.github.com/repos/launchdarkly/python-server-sdk/issues/67/labels{/name}", "comments_url": "https://api.github.com/repos/launchdarkly/python-server-sdk/issues/67/comments", "events_url": "https://api.github.com/repos/launchdarkly/python-server-sdk/issues/67/events", "html_url": "https://github.com/launchdarkly/python-server-sdk/issues/67", "id": 197711086, "node_id": "MDU6SXNzdWUxOTc3MTEwODY=", "number": 67, "title": "RedisFeatureStore should handle redis outage", "user": {"login": "pdsarin", "id": 765819, "node_id": "MDQ6VXNlcjc2NTgxOQ==", "avatar_url": "https://avatars3.githubusercontent.com/u/765819?v=4", "gravatar_id": "", "url": "https://api.github.com/users/pdsarin", "html_url": "https://github.com/pdsarin", "followers_url": "https://api.github.com/users/pdsarin/followers", "following_url": "https://api.github.com/users/pdsarin/following{/other_user}", "gists_url": "https://api.github.com/users/pdsarin/gists{/gist_id}", "starred_url": "https://api.github.com/users/pdsarin/starred{/owner}{/repo}", "subscriptions_url": "https://api.github.com/users/pdsarin/subscriptions", "organizations_url": "https://api.github.com/users/pdsarin/orgs", "repos_url": "https://api.github.com/users/pdsarin/repos", "events_url": "https://api.github.com/users/pdsarin/events{/privacy}", "received_events_url": "https://api.github.com/users/pdsarin/received_events", "type": "User", "site_admin": false}, "labels": [], "state": "closed", "locked": false, "assignee": null, "assignees": [], "milestone": null, "comments": 3, "created_at": "2016-12-27T14:34:05Z", "updated_at": "2017-01-21T12:06:58Z", "closed_at": "2017-01-10T21:05:02Z", "author_association": "NONE", "active_lock_reason": null, "body": "From my reading of the code and from some limited testing, the LaunchDarkly client gracefully handles unavailability of the LaunchDarkly service.\r\n\r\nThe RedisFeatureStore does not appear to handle outages gracefully. IMO it should return the default when redis is unavailable. (I discovered the problem when I had my redis URL misconfigured while running in ldd mode.)", "performed_via_github_app": null, "score": 1.0}, {"url": "https://api.github.com/repos/launchdarkly/python-server-sdk/issues/65", "repository_url": "https://api.github.com/repos/launchdarkly/python-server-sdk", "labels_url": "https://api.github.com/repos/launchdarkly/python-server-sdk/issues/65/labels{/name}", "comments_url": "https://api.github.com/repos/launchdarkly/python-server-sdk/issues/65/comments", "events_url": "https://api.github.com/repos/launchdarkly/python-server-sdk/issues/65/events", "html_url": "https://github.com/launchdarkly/python-server-sdk/issues/65", "id": 195435009, "node_id": "MDU6SXNzdWUxOTU0MzUwMDk=", "number": 65, "title": "\"Missing or blank sdk key\" log warning message upon importing ldclient", "user": {"login": "pdsarin", "id": 765819, "node_id": "MDQ6VXNlcjc2NTgxOQ==", "avatar_url": "https://avatars3.githubusercontent.com/u/765819?v=4", "gravatar_id": "", "url": "https://api.github.com/users/pdsarin", "html_url": "https://github.com/pdsarin", "followers_url": "https://api.github.com/users/pdsarin/followers", "following_url": "https://api.github.com/users/pdsarin/following{/other_user}", "gists_url": "https://api.github.com/users/pdsarin/gists{/gist_id}", "starred_url": "https://api.github.com/users/pdsarin/starred{/owner}{/repo}", "subscriptions_url": "https://api.github.com/users/pdsarin/subscriptions", "organizations_url": "https://api.github.com/users/pdsarin/orgs", "repos_url": "https://api.github.com/users/pdsarin/repos", "events_url": "https://api.github.com/users/pdsarin/events{/privacy}", "received_events_url": "https://api.github.com/users/pdsarin/received_events", "type": "User", "site_admin": false}, "labels": [], "state": "closed", "locked": false, "assignee": null, "assignees": [], "milestone": null, "comments": 1, "created_at": "2016-12-14T04:02:00Z", "updated_at": "2017-04-18T18:00:11Z", "closed_at": "2017-04-18T18:00:11Z", "author_association": "NONE", "active_lock_reason": null, "body": "A warning is logged upon import of ldclient. IMO should either be logged at a lower level, or not at all as there's nothing I can do to prevent it.\r\n\r\n`WARNING  2016-12-13 23:53:09,950 config.py:43 - ldclient.util - __init__: Missing or blank sdk_key.`\r\n\r\n", "performed_via_github_app": null, "score": 1.0}, {"url": "https://api.github.com/repos/launchdarkly/python-server-sdk/issues/63", "repository_url": "https://api.github.com/repos/launchdarkly/python-server-sdk", "labels_url": "https://api.github.com/repos/launchdarkly/python-server-sdk/issues/63/labels{/name}", "comments_url": "https://api.github.com/repos/launchdarkly/python-server-sdk/issues/63/comments", "events_url": "https://api.github.com/repos/launchdarkly/python-server-sdk/issues/63/events", "html_url": "https://github.com/launchdarkly/python-server-sdk/issues/63", "id": 187410677, "node_id": "MDU6SXNzdWUxODc0MTA2Nzc=", "number": 63, "title": "Allow updating of SDK key", "user": {"login": "drichelson", "id": 602409, "node_id": "MDQ6VXNlcjYwMjQwOQ==", "avatar_url": "https://avatars3.githubusercontent.com/u/602409?v=4", "gravatar_id": "", "url": "https://api.github.com/users/drichelson", "html_url": "https://github.com/drichelson", "followers_url": "https://api.github.com/users/drichelson/followers", "following_url": "https://api.github.com/users/drichelson/following{/other_user}", "gists_url": "https://api.github.com/users/drichelson/gists{/gist_id}", "starred_url": "https://api.github.com/users/drichelson/starred{/owner}{/repo}", "subscriptions_url": "https://api.github.com/users/drichelson/subscriptions", "organizations_url": "https://api.github.com/users/drichelson/orgs", "repos_url": "https://api.github.com/users/drichelson/repos", "events_url": "https://api.github.com/users/drichelson/events{/privacy}", "received_events_url": "https://api.github.com/users/drichelson/received_events", "type": "User", "site_admin": false}, "labels": [], "state": "closed", "locked": false, "assignee": null, "assignees": [], "milestone": null, "comments": 1, "created_at": "2016-11-04T18:48:32Z", "updated_at": "2017-01-10T21:05:34Z", "closed_at": "2017-01-10T21:05:34Z", "author_association": "CONTRIBUTOR", "active_lock_reason": null, "body": "This allows for SDK key resets without a restart of your application", "performed_via_github_app": null, "score": 1.0}, {"url": "https://api.github.com/repos/launchdarkly/python-server-sdk/issues/61", "repository_url": "https://api.github.com/repos/launchdarkly/python-server-sdk", "labels_url": "https://api.github.com/repos/launchdarkly/python-server-sdk/issues/61/labels{/name}", "comments_url": "https://api.github.com/repos/launchdarkly/python-server-sdk/issues/61/comments", "events_url": "https://api.github.com/repos/launchdarkly/python-server-sdk/issues/61/events", "html_url": "https://github.com/launchdarkly/python-server-sdk/issues/61", "id": 185984227, "node_id": "MDU6SXNzdWUxODU5ODQyMjc=", "number": 61, "title": "Allow client to be stopped and restarted", "user": {"login": "drichelson", "id": 602409, "node_id": "MDQ6VXNlcjYwMjQwOQ==", "avatar_url": "https://avatars3.githubusercontent.com/u/602409?v=4", "gravatar_id": "", "url": "https://api.github.com/users/drichelson", "html_url": "https://github.com/drichelson", "followers_url": "https://api.github.com/users/drichelson/followers", "following_url": "https://api.github.com/users/drichelson/following{/other_user}", "gists_url": "https://api.github.com/users/drichelson/gists{/gist_id}", "starred_url": "https://api.github.com/users/drichelson/starred{/owner}{/repo}", "subscriptions_url": "https://api.github.com/users/drichelson/subscriptions", "organizations_url": "https://api.github.com/users/drichelson/orgs", "repos_url": "https://api.github.com/users/drichelson/repos", "events_url": "https://api.github.com/users/drichelson/events{/privacy}", "received_events_url": "https://api.github.com/users/drichelson/received_events", "type": "User", "site_admin": false}, "labels": [], "state": "closed", "locked": false, "assignee": null, "assignees": [], "milestone": null, "comments": 0, "created_at": "2016-10-28T18:00:54Z", "updated_at": "2018-10-09T18:37:46Z", "closed_at": "2018-10-09T18:37:46Z", "author_association": "CONTRIBUTOR", "active_lock_reason": null, "body": "This behavior doesn't seem to work in this situation: Configure the client with an invalid SDK key, then attempt to stop the client. Ensure that a new SDK key is properly passed through to all http clients. \n", "performed_via_github_app": null, "score": 1.0}, {"url": "https://api.github.com/repos/launchdarkly/python-server-sdk/issues/57", "repository_url": "https://api.github.com/repos/launchdarkly/python-server-sdk", "labels_url": "https://api.github.com/repos/launchdarkly/python-server-sdk/issues/57/labels{/name}", "comments_url": "https://api.github.com/repos/launchdarkly/python-server-sdk/issues/57/comments", "events_url": "https://api.github.com/repos/launchdarkly/python-server-sdk/issues/57/events", "html_url": "https://github.com/launchdarkly/python-server-sdk/issues/57", "id": 184336692, "node_id": "MDU6SXNzdWUxODQzMzY2OTI=", "number": 57, "title": "Unhandled exception in event consumer. Analytics events were not processed.", "user": {"login": "kjwilcox", "id": 6686641, "node_id": "MDQ6VXNlcjY2ODY2NDE=", "avatar_url": "https://avatars0.githubusercontent.com/u/6686641?v=4", "gravatar_id": "", "url": "https://api.github.com/users/kjwilcox", "html_url": "https://github.com/kjwilcox", "followers_url": "https://api.github.com/users/kjwilcox/followers", "following_url": "https://api.github.com/users/kjwilcox/following{/other_user}", "gists_url": "https://api.github.com/users/kjwilcox/gists{/gist_id}", "starred_url": "https://api.github.com/users/kjwilcox/starred{/owner}{/repo}", "subscriptions_url": "https://api.github.com/users/kjwilcox/subscriptions", "organizations_url": "https://api.github.com/users/kjwilcox/orgs", "repos_url": "https://api.github.com/users/kjwilcox/repos", "events_url": "https://api.github.com/users/kjwilcox/events{/privacy}", "received_events_url": "https://api.github.com/users/kjwilcox/received_events", "type": "User", "site_admin": false}, "labels": [], "state": "closed", "locked": false, "assignee": null, "assignees": [], "milestone": null, "comments": 4, "created_at": "2016-10-20T20:48:10Z", "updated_at": "2016-10-26T18:28:10Z", "closed_at": "2016-10-26T18:28:09Z", "author_association": "NONE", "active_lock_reason": null, "body": "When calling `launchdarkly_client.toggle()`, we often see an error log with the following traceback:\n\n```\nTraceback (most recent call last):\n  File \"/path/to/virtualenv/lib/python3.5/site-packages/ldclient/event_consumer.py\", line 50, in do_send\n    data=json.dumps(body))\n  File \"/usr/local/python/lib/python3.5/json/__init__.py\", line 230, in dumps\n    return _default_encoder.encode(obj)\n  File \"/usr/local/python/lib/python3.5/json/encoder.py\", line 198, in encode\n    chunks = self.iterencode(o, _one_shot=True)\n  File \"/usr/local/python/lib/python3.5/json/encoder.py\", line 256, in iterencode\n    return _iterencode(o, 0)\n  File \"/usr/local/python/lib/python3.5/json/encoder.py\", line 179, in default\n    raise TypeError(repr(o) + \" is not JSON serializable\")\nTypeError: <object object at 0x7f3b18c7c230> is not JSON serializable\n```\n\nThe user object we are providing to `.toggle()` does not contain any non-json-serializable fields. Example: `{'anonymous': True, 'key': 'SECRET', 'custom': {'client': 'sandbox', 'roles': (), 'superuser': False}}`\n\nWe are currently using version 0.20.3, but this problem repros on 3.0.0. Running on Python 3.5.2 on Ubuntu 14.04.\n\nIs there a way for us to opt-out of these failing analytics events? Or can the this client library be updated to fix this error?\n", "performed_via_github_app": null, "score": 1.0}, {"url": "https://api.github.com/repos/launchdarkly/python-server-sdk/issues/56", "repository_url": "https://api.github.com/repos/launchdarkly/python-server-sdk", "labels_url": "https://api.github.com/repos/launchdarkly/python-server-sdk/issues/56/labels{/name}", "comments_url": "https://api.github.com/repos/launchdarkly/python-server-sdk/issues/56/comments", "events_url": "https://api.github.com/repos/launchdarkly/python-server-sdk/issues/56/events", "html_url": "https://github.com/launchdarkly/python-server-sdk/issues/56", "id": 176968503, "node_id": "MDU6SXNzdWUxNzY5Njg1MDM=", "number": 56, "title": "non-JSON-serializable custom attributes cause events to be silently dropped.", "user": {"login": "pkaeding", "id": 13951, "node_id": "MDQ6VXNlcjEzOTUx", "avatar_url": "https://avatars2.githubusercontent.com/u/13951?v=4", "gravatar_id": "", "url": "https://api.github.com/users/pkaeding", "html_url": "https://github.com/pkaeding", "followers_url": "https://api.github.com/users/pkaeding/followers", "following_url": "https://api.github.com/users/pkaeding/following{/other_user}", "gists_url": "https://api.github.com/users/pkaeding/gists{/gist_id}", "starred_url": "https://api.github.com/users/pkaeding/starred{/owner}{/repo}", "subscriptions_url": "https://api.github.com/users/pkaeding/subscriptions", "organizations_url": "https://api.github.com/users/pkaeding/orgs", "repos_url": "https://api.github.com/users/pkaeding/repos", "events_url": "https://api.github.com/users/pkaeding/events{/privacy}", "received_events_url": "https://api.github.com/users/pkaeding/received_events", "type": "User", "site_admin": false}, "labels": [], "state": "closed", "locked": false, "assignee": null, "assignees": [], "milestone": null, "comments": 1, "created_at": "2016-09-14T17:23:26Z", "updated_at": "2016-10-26T18:30:07Z", "closed_at": "2016-10-26T18:30:07Z", "author_association": "CONTRIBUTOR", "active_lock_reason": null, "body": "For instance, if you create a `datetime.datetime` value and put it in a user's custom attributes, the event will fail to be sent.\n", "performed_via_github_app": null, "score": 1.0}, {"url": "https://api.github.com/repos/launchdarkly/python-server-sdk/issues/43", "repository_url": "https://api.github.com/repos/launchdarkly/python-server-sdk", "labels_url": "https://api.github.com/repos/launchdarkly/python-server-sdk/issues/43/labels{/name}", "comments_url": "https://api.github.com/repos/launchdarkly/python-server-sdk/issues/43/comments", "events_url": "https://api.github.com/repos/launchdarkly/python-server-sdk/issues/43/events", "html_url": "https://github.com/launchdarkly/python-server-sdk/issues/43", "id": 153675981, "node_id": "MDU6SXNzdWUxNTM2NzU5ODE=", "number": 43, "title": "Set up CodeClimate test coverage", "user": {"login": "albertyw", "id": 3151040, "node_id": "MDQ6VXNlcjMxNTEwNDA=", "avatar_url": "https://avatars3.githubusercontent.com/u/3151040?v=4", "gravatar_id": "", "url": "https://api.github.com/users/albertyw", "html_url": "https://github.com/albertyw", "followers_url": "https://api.github.com/users/albertyw/followers", "following_url": "https://api.github.com/users/albertyw/following{/other_user}", "gists_url": "https://api.github.com/users/albertyw/gists{/gist_id}", "starred_url": "https://api.github.com/users/albertyw/starred{/owner}{/repo}", "subscriptions_url": "https://api.github.com/users/albertyw/subscriptions", "organizations_url": "https://api.github.com/users/albertyw/orgs", "repos_url": "https://api.github.com/users/albertyw/repos", "events_url": "https://api.github.com/users/albertyw/events{/privacy}", "received_events_url": "https://api.github.com/users/albertyw/received_events", "type": "User", "site_admin": false}, "labels": [], "state": "closed", "locked": false, "assignee": null, "assignees": [], "milestone": null, "comments": 1, "created_at": "2016-05-08T20:31:17Z", "updated_at": "2017-04-25T23:29:05Z", "closed_at": "2017-04-25T23:28:53Z", "author_association": "CONTRIBUTOR", "active_lock_reason": null, "body": "", "performed_via_github_app": null, "score": 1.0}, {"url": "https://api.github.com/repos/launchdarkly/python-server-sdk/issues/37", "repository_url": "https://api.github.com/repos/launchdarkly/python-server-sdk", "labels_url": "https://api.github.com/repos/launchdarkly/python-server-sdk/issues/37/labels{/name}", "comments_url": "https://api.github.com/repos/launchdarkly/python-server-sdk/issues/37/comments", "events_url": "https://api.github.com/repos/launchdarkly/python-server-sdk/issues/37/events", "html_url": "https://github.com/launchdarkly/python-server-sdk/issues/37", "id": 128945372, "node_id": "MDU6SXNzdWUxMjg5NDUzNzI=", "number": 37, "title": "Timeouts when starting twisted impl against ld-daemon", "user": {"login": "mrdon", "id": 18610, "node_id": "MDQ6VXNlcjE4NjEw", "avatar_url": "https://avatars3.githubusercontent.com/u/18610?v=4", "gravatar_id": "", "url": "https://api.github.com/users/mrdon", "html_url": "https://github.com/mrdon", "followers_url": "https://api.github.com/users/mrdon/followers", "following_url": "https://api.github.com/users/mrdon/following{/other_user}", "gists_url": "https://api.github.com/users/mrdon/gists{/gist_id}", "starred_url": "https://api.github.com/users/mrdon/starred{/owner}{/repo}", "subscriptions_url": "https://api.github.com/users/mrdon/subscriptions", "organizations_url": "https://api.github.com/users/mrdon/orgs", "repos_url": "https://api.github.com/users/mrdon/repos", "events_url": "https://api.github.com/users/mrdon/events{/privacy}", "received_events_url": "https://api.github.com/users/mrdon/received_events", "type": "User", "site_admin": false}, "labels": [], "state": "closed", "locked": false, "assignee": null, "assignees": [], "milestone": null, "comments": 1, "created_at": "2016-01-26T21:20:15Z", "updated_at": "2016-02-09T01:24:51Z", "closed_at": "2016-02-09T01:24:51Z", "author_association": "CONTRIBUTOR", "active_lock_reason": null, "body": "The problem is if nothing is in redis, all requests time out.\n", "performed_via_github_app": null, "score": 1.0}, {"url": "https://api.github.com/repos/launchdarkly/python-server-sdk/issues/35", "repository_url": "https://api.github.com/repos/launchdarkly/python-server-sdk", "labels_url": "https://api.github.com/repos/launchdarkly/python-server-sdk/issues/35/labels{/name}", "comments_url": "https://api.github.com/repos/launchdarkly/python-server-sdk/issues/35/comments", "events_url": "https://api.github.com/repos/launchdarkly/python-server-sdk/issues/35/events", "html_url": "https://github.com/launchdarkly/python-server-sdk/issues/35", "id": 124152462, "node_id": "MDU6SXNzdWUxMjQxNTI0NjI=", "number": 35, "title": "Strict requirements are no fun", "user": {"login": "crempp", "id": 524559, "node_id": "MDQ6VXNlcjUyNDU1OQ==", "avatar_url": "https://avatars2.githubusercontent.com/u/524559?v=4", "gravatar_id": "", "url": "https://api.github.com/users/crempp", "html_url": "https://github.com/crempp", "followers_url": "https://api.github.com/users/crempp/followers", "following_url": "https://api.github.com/users/crempp/following{/other_user}", "gists_url": "https://api.github.com/users/crempp/gists{/gist_id}", "starred_url": "https://api.github.com/users/crempp/starred{/owner}{/repo}", "subscriptions_url": "https://api.github.com/users/crempp/subscriptions", "organizations_url": "https://api.github.com/users/crempp/orgs", "repos_url": "https://api.github.com/users/crempp/repos", "events_url": "https://api.github.com/users/crempp/events{/privacy}", "received_events_url": "https://api.github.com/users/crempp/received_events", "type": "User", "site_admin": false}, "labels": [], "state": "closed", "locked": false, "assignee": null, "assignees": [], "milestone": null, "comments": 4, "created_at": "2015-12-29T02:10:37Z", "updated_at": "2016-05-20T00:03:46Z", "closed_at": "2016-05-19T23:00:08Z", "author_association": "NONE", "active_lock_reason": null, "body": "Would it be possible to update the requirements.txt to not use strict (==) requirements? This has forced me to downgrade requests to 2.4.0.\n", "performed_via_github_app": null, "score": 1.0}, {"url": "https://api.github.com/repos/launchdarkly/python-server-sdk/issues/33", "repository_url": "https://api.github.com/repos/launchdarkly/python-server-sdk", "labels_url": "https://api.github.com/repos/launchdarkly/python-server-sdk/issues/33/labels{/name}", "comments_url": "https://api.github.com/repos/launchdarkly/python-server-sdk/issues/33/comments", "events_url": "https://api.github.com/repos/launchdarkly/python-server-sdk/issues/33/events", "html_url": "https://github.com/launchdarkly/python-server-sdk/issues/33", "id": 121618762, "node_id": "MDU6SXNzdWUxMjE2MTg3NjI=", "number": 33, "title": "Python client fails when no config set", "user": {"login": "trungly", "id": 47417, "node_id": "MDQ6VXNlcjQ3NDE3", "avatar_url": "https://avatars1.githubusercontent.com/u/47417?v=4", "gravatar_id": "", "url": "https://api.github.com/users/trungly", "html_url": "https://github.com/trungly", "followers_url": "https://api.github.com/users/trungly/followers", "following_url": "https://api.github.com/users/trungly/following{/other_user}", "gists_url": "https://api.github.com/users/trungly/gists{/gist_id}", "starred_url": "https://api.github.com/users/trungly/starred{/owner}{/repo}", "subscriptions_url": "https://api.github.com/users/trungly/subscriptions", "organizations_url": "https://api.github.com/users/trungly/orgs", "repos_url": "https://api.github.com/users/trungly/repos", "events_url": "https://api.github.com/users/trungly/events{/privacy}", "received_events_url": "https://api.github.com/users/trungly/received_events", "type": "User", "site_admin": false}, "labels": [], "state": "closed", "locked": false, "assignee": null, "assignees": [], "milestone": null, "comments": 2, "created_at": "2015-12-11T01:58:39Z", "updated_at": "2015-12-11T19:06:20Z", "closed_at": "2015-12-11T17:41:18Z", "author_association": "CONTRIBUTOR", "active_lock_reason": null, "body": "I'm got the following when I tried the Quickstart tutorial:\n\n```\n\nTraceback (most recent call last):\n  File \"test.py\", line 4, in <module>\n    client = LDClient(\"api-094349dd-49bf-4aa5-91a7-7ad9bbbd1817\")\n  File \"/Users/tly/.virtualenvs/launchdarkly/lib/python2.7/site-packages/ldclient/client.py\", line 153, in __init__\n    self._store = config.feature_store_class()\nAttributeError: 'NoneType' object has no attribute 'feature_store_class'\n```\n\nI'll put together a pull request to fix this.\n", "performed_via_github_app": null, "score": 1.0}, {"url": "https://api.github.com/repos/launchdarkly/python-server-sdk/issues/29", "repository_url": "https://api.github.com/repos/launchdarkly/python-server-sdk", "labels_url": "https://api.github.com/repos/launchdarkly/python-server-sdk/issues/29/labels{/name}", "comments_url": "https://api.github.com/repos/launchdarkly/python-server-sdk/issues/29/comments", "events_url": "https://api.github.com/repos/launchdarkly/python-server-sdk/issues/29/events", "html_url": "https://github.com/launchdarkly/python-server-sdk/issues/29", "id": 111556076, "node_id": "MDU6SXNzdWUxMTE1NTYwNzY=", "number": 29, "title": "Use expiringdict from PyPI", "user": {"login": "albertyw", "id": 3151040, "node_id": "MDQ6VXNlcjMxNTEwNDA=", "avatar_url": "https://avatars3.githubusercontent.com/u/3151040?v=4", "gravatar_id": "", "url": "https://api.github.com/users/albertyw", "html_url": "https://github.com/albertyw", "followers_url": "https://api.github.com/users/albertyw/followers", "following_url": "https://api.github.com/users/albertyw/following{/other_user}", "gists_url": "https://api.github.com/users/albertyw/gists{/gist_id}", "starred_url": "https://api.github.com/users/albertyw/starred{/owner}{/repo}", "subscriptions_url": "https://api.github.com/users/albertyw/subscriptions", "organizations_url": "https://api.github.com/users/albertyw/orgs", "repos_url": "https://api.github.com/users/albertyw/repos", "events_url": "https://api.github.com/users/albertyw/events{/privacy}", "received_events_url": "https://api.github.com/users/albertyw/received_events", "type": "User", "site_admin": false}, "labels": [], "state": "closed", "locked": false, "assignee": null, "assignees": [], "milestone": null, "comments": 3, "created_at": "2015-10-15T06:51:43Z", "updated_at": "2018-10-14T03:20:32Z", "closed_at": "2018-10-14T03:20:32Z", "author_association": "CONTRIBUTOR", "active_lock_reason": null, "body": "I notice that a full copy of the ExpiringDict file is at https://github.com/launchdarkly/python-client/blob/4cf65590c0523fe22641d60bf655214e061be3e2/ldclient/expiringdict.py with the only difference being line 17.  Is there a reason why ExpringDict isn't being imported as a package from PyPI instead?  IANL, but I assumed that the NOTICE.txt would be sufficient to cover attribution requirements of the apache license.  \n", "performed_via_github_app": null, "score": 1.0}, {"url": "https://api.github.com/repos/launchdarkly/python-server-sdk/issues/28", "repository_url": "https://api.github.com/repos/launchdarkly/python-server-sdk", "labels_url": "https://api.github.com/repos/launchdarkly/python-server-sdk/issues/28/labels{/name}", "comments_url": "https://api.github.com/repos/launchdarkly/python-server-sdk/issues/28/comments", "events_url": "https://api.github.com/repos/launchdarkly/python-server-sdk/issues/28/events", "html_url": "https://github.com/launchdarkly/python-server-sdk/issues/28", "id": 111555546, "node_id": "MDU6SXNzdWUxMTE1NTU1NDY=", "number": 28, "title": "Move development and contributing info to CONTRIBUTING.md", "user": {"login": "albertyw", "id": 3151040, "node_id": "MDQ6VXNlcjMxNTEwNDA=", "avatar_url": "https://avatars3.githubusercontent.com/u/3151040?v=4", "gravatar_id": "", "url": "https://api.github.com/users/albertyw", "html_url": "https://github.com/albertyw", "followers_url": "https://api.github.com/users/albertyw/followers", "following_url": "https://api.github.com/users/albertyw/following{/other_user}", "gists_url": "https://api.github.com/users/albertyw/gists{/gist_id}", "starred_url": "https://api.github.com/users/albertyw/starred{/owner}{/repo}", "subscriptions_url": "https://api.github.com/users/albertyw/subscriptions", "organizations_url": "https://api.github.com/users/albertyw/orgs", "repos_url": "https://api.github.com/users/albertyw/repos", "events_url": "https://api.github.com/users/albertyw/events{/privacy}", "received_events_url": "https://api.github.com/users/albertyw/received_events", "type": "User", "site_admin": false}, "labels": [], "state": "closed", "locked": false, "assignee": null, "assignees": [], "milestone": null, "comments": 0, "created_at": "2015-10-15T06:45:38Z", "updated_at": "2016-05-19T23:23:21Z", "closed_at": "2016-05-19T23:23:21Z", "author_association": "CONTRIBUTOR", "active_lock_reason": null, "body": "There's currently two sections about development and contributing to this repo.  They should probably be moved to a `CONTRIBUTING.md` like in https://github.com/launchdarkly/ruby-client/blob/master/CONTRIBUTING.md.  See also https://github.com/launchdarkly/ruby-client/pull/40\n", "performed_via_github_app": null, "score": 1.0}, {"url": "https://api.github.com/repos/launchdarkly/python-server-sdk/issues/21", "repository_url": "https://api.github.com/repos/launchdarkly/python-server-sdk", "labels_url": "https://api.github.com/repos/launchdarkly/python-server-sdk/issues/21/labels{/name}", "comments_url": "https://api.github.com/repos/launchdarkly/python-server-sdk/issues/21/comments", "events_url": "https://api.github.com/repos/launchdarkly/python-server-sdk/issues/21/events", "html_url": "https://github.com/launchdarkly/python-server-sdk/issues/21", "id": 106647479, "node_id": "MDU6SXNzdWUxMDY2NDc0Nzk=", "number": 21, "title": "Support configured defaults", "user": {"login": "mrdon", "id": 18610, "node_id": "MDQ6VXNlcjE4NjEw", "avatar_url": "https://avatars3.githubusercontent.com/u/18610?v=4", "gravatar_id": "", "url": "https://api.github.com/users/mrdon", "html_url": "https://github.com/mrdon", "followers_url": "https://api.github.com/users/mrdon/followers", "following_url": "https://api.github.com/users/mrdon/following{/other_user}", "gists_url": "https://api.github.com/users/mrdon/gists{/gist_id}", "starred_url": "https://api.github.com/users/mrdon/starred{/owner}{/repo}", "subscriptions_url": "https://api.github.com/users/mrdon/subscriptions", "organizations_url": "https://api.github.com/users/mrdon/orgs", "repos_url": "https://api.github.com/users/mrdon/repos", "events_url": "https://api.github.com/users/mrdon/events{/privacy}", "received_events_url": "https://api.github.com/users/mrdon/received_events", "type": "User", "site_admin": false}, "labels": [], "state": "closed", "locked": false, "assignee": null, "assignees": [], "milestone": null, "comments": 0, "created_at": "2015-09-15T21:09:29Z", "updated_at": "2015-10-07T05:53:45Z", "closed_at": "2015-10-07T05:53:45Z", "author_association": "CONTRIBUTOR", "active_lock_reason": null, "body": "LDClient should be able to take a dict of default values to allow the centralization of defaults, especially useful in offline mode supporting different environments.\n", "performed_via_github_app": null, "score": 1.0}, {"url": "https://api.github.com/repos/launchdarkly/python-server-sdk/issues/20", "repository_url": "https://api.github.com/repos/launchdarkly/python-server-sdk", "labels_url": "https://api.github.com/repos/launchdarkly/python-server-sdk/issues/20/labels{/name}", "comments_url": "https://api.github.com/repos/launchdarkly/python-server-sdk/issues/20/comments", "events_url": "https://api.github.com/repos/launchdarkly/python-server-sdk/issues/20/events", "html_url": "https://github.com/launchdarkly/python-server-sdk/issues/20", "id": 105661653, "node_id": "MDU6SXNzdWUxMDU2NjE2NTM=", "number": 20, "title": "RWLock implementation should guard against negative readers count", "user": {"login": "jkodumal", "id": 19426, "node_id": "MDQ6VXNlcjE5NDI2", "avatar_url": "https://avatars2.githubusercontent.com/u/19426?v=4", "gravatar_id": "", "url": "https://api.github.com/users/jkodumal", "html_url": "https://github.com/jkodumal", "followers_url": "https://api.github.com/users/jkodumal/followers", "following_url": "https://api.github.com/users/jkodumal/following{/other_user}", "gists_url": "https://api.github.com/users/jkodumal/gists{/gist_id}", "starred_url": "https://api.github.com/users/jkodumal/starred{/owner}{/repo}", "subscriptions_url": "https://api.github.com/users/jkodumal/subscriptions", "organizations_url": "https://api.github.com/users/jkodumal/orgs", "repos_url": "https://api.github.com/users/jkodumal/repos", "events_url": "https://api.github.com/users/jkodumal/events{/privacy}", "received_events_url": "https://api.github.com/users/jkodumal/received_events", "type": "User", "site_admin": false}, "labels": [], "state": "closed", "locked": false, "assignee": null, "assignees": [], "milestone": null, "comments": 0, "created_at": "2015-09-09T19:01:01Z", "updated_at": "2018-10-14T03:19:18Z", "closed_at": "2018-10-14T03:19:18Z", "author_association": "CONTRIBUTOR", "active_lock_reason": null, "body": "", "performed_via_github_app": null, "score": 1.0}, {"url": "https://api.github.com/repos/launchdarkly/python-server-sdk/issues/18", "repository_url": "https://api.github.com/repos/launchdarkly/python-server-sdk", "labels_url": "https://api.github.com/repos/launchdarkly/python-server-sdk/issues/18/labels{/name}", "comments_url": "https://api.github.com/repos/launchdarkly/python-server-sdk/issues/18/comments", "events_url": "https://api.github.com/repos/launchdarkly/python-server-sdk/issues/18/events", "html_url": "https://github.com/launchdarkly/python-server-sdk/issues/18", "id": 105481772, "node_id": "MDU6SXNzdWUxMDU0ODE3NzI=", "number": 18, "title": "Twisted support", "user": {"login": "mrdon", "id": 18610, "node_id": "MDQ6VXNlcjE4NjEw", "avatar_url": "https://avatars3.githubusercontent.com/u/18610?v=4", "gravatar_id": "", "url": "https://api.github.com/users/mrdon", "html_url": "https://github.com/mrdon", "followers_url": "https://api.github.com/users/mrdon/followers", "following_url": "https://api.github.com/users/mrdon/following{/other_user}", "gists_url": "https://api.github.com/users/mrdon/gists{/gist_id}", "starred_url": "https://api.github.com/users/mrdon/starred{/owner}{/repo}", "subscriptions_url": "https://api.github.com/users/mrdon/subscriptions", "organizations_url": "https://api.github.com/users/mrdon/orgs", "repos_url": "https://api.github.com/users/mrdon/repos", "events_url": "https://api.github.com/users/mrdon/events{/privacy}", "received_events_url": "https://api.github.com/users/mrdon/received_events", "type": "User", "site_admin": false}, "labels": [], "state": "closed", "locked": false, "assignee": null, "assignees": [], "milestone": null, "comments": 1, "created_at": "2015-09-08T22:26:56Z", "updated_at": "2015-09-14T23:29:44Z", "closed_at": "2015-09-14T23:29:44Z", "author_association": "CONTRIBUTOR", "active_lock_reason": null, "body": "Would be nice to have twisted support\n", "performed_via_github_app": null, "score": 1.0}, {"url": "https://api.github.com/repos/launchdarkly/python-server-sdk/issues/13", "repository_url": "https://api.github.com/repos/launchdarkly/python-server-sdk", "labels_url": "https://api.github.com/repos/launchdarkly/python-server-sdk/issues/13/labels{/name}", "comments_url": "https://api.github.com/repos/launchdarkly/python-server-sdk/issues/13/comments", "events_url": "https://api.github.com/repos/launchdarkly/python-server-sdk/issues/13/events", "html_url": "https://github.com/launchdarkly/python-server-sdk/issues/13", "id": 74548831, "node_id": "MDU6SXNzdWU3NDU0ODgzMQ==", "number": 13, "title": "Default consumer makes `flush()` asynchronous", "user": {"login": "jkodumal", "id": 19426, "node_id": "MDQ6VXNlcjE5NDI2", "avatar_url": "https://avatars2.githubusercontent.com/u/19426?v=4", "gravatar_id": "", "url": "https://api.github.com/users/jkodumal", "html_url": "https://github.com/jkodumal", "followers_url": "https://api.github.com/users/jkodumal/followers", "following_url": "https://api.github.com/users/jkodumal/following{/other_user}", "gists_url": "https://api.github.com/users/jkodumal/gists{/gist_id}", "starred_url": "https://api.github.com/users/jkodumal/starred{/owner}{/repo}", "subscriptions_url": "https://api.github.com/users/jkodumal/subscriptions", "organizations_url": "https://api.github.com/users/jkodumal/orgs", "repos_url": "https://api.github.com/users/jkodumal/repos", "events_url": "https://api.github.com/users/jkodumal/events{/privacy}", "received_events_url": "https://api.github.com/users/jkodumal/received_events", "type": "User", "site_admin": false}, "labels": [], "state": "closed", "locked": false, "assignee": null, "assignees": [], "milestone": null, "comments": 1, "created_at": "2015-05-09T01:13:20Z", "updated_at": "2015-09-08T22:52:35Z", "closed_at": "2015-09-08T22:52:35Z", "author_association": "CONTRIBUTOR", "active_lock_reason": null, "body": "`ldclient.flush()`should be a synchronous operation. However, the default consumer configuration causes this to be asynchronous.\n", "performed_via_github_app": null, "score": 1.0}]}