{"total_count": 11, "incomplete_results": false, "items": [{"url": "https://api.github.com/repos/google/importlab/issues/37", "repository_url": "https://api.github.com/repos/google/importlab", "labels_url": "https://api.github.com/repos/google/importlab/issues/37/labels{/name}", "comments_url": "https://api.github.com/repos/google/importlab/issues/37/comments", "events_url": "https://api.github.com/repos/google/importlab/issues/37/events", "html_url": "https://github.com/google/importlab/issues/37", "id": 390921748, "node_id": "MDU6SXNzdWUzOTA5MjE3NDg=", "number": 37, "title": "module recorded as \"unreadable\" when one of its direct dependencies is unloadable", "user": {"login": "rchen152", "id": 4142312, "node_id": "MDQ6VXNlcjQxNDIzMTI=", "avatar_url": "https://avatars2.githubusercontent.com/u/4142312?v=4", "gravatar_id": "", "url": "https://api.github.com/users/rchen152", "html_url": "https://github.com/rchen152", "followers_url": "https://api.github.com/users/rchen152/followers", "following_url": "https://api.github.com/users/rchen152/following{/other_user}", "gists_url": "https://api.github.com/users/rchen152/gists{/gist_id}", "starred_url": "https://api.github.com/users/rchen152/starred{/owner}{/repo}", "subscriptions_url": "https://api.github.com/users/rchen152/subscriptions", "organizations_url": "https://api.github.com/users/rchen152/orgs", "repos_url": "https://api.github.com/users/rchen152/repos", "events_url": "https://api.github.com/users/rchen152/events{/privacy}", "received_events_url": "https://api.github.com/users/rchen152/received_events", "type": "User", "site_admin": false}, "labels": [], "state": "closed", "locked": false, "assignee": {"login": "rchen152", "id": 4142312, "node_id": "MDQ6VXNlcjQxNDIzMTI=", "avatar_url": "https://avatars2.githubusercontent.com/u/4142312?v=4", "gravatar_id": "", "url": "https://api.github.com/users/rchen152", "html_url": "https://github.com/rchen152", "followers_url": "https://api.github.com/users/rchen152/followers", "following_url": "https://api.github.com/users/rchen152/following{/other_user}", "gists_url": "https://api.github.com/users/rchen152/gists{/gist_id}", "starred_url": "https://api.github.com/users/rchen152/starred{/owner}{/repo}", "subscriptions_url": "https://api.github.com/users/rchen152/subscriptions", "organizations_url": "https://api.github.com/users/rchen152/orgs", "repos_url": "https://api.github.com/users/rchen152/repos", "events_url": "https://api.github.com/users/rchen152/events{/privacy}", "received_events_url": "https://api.github.com/users/rchen152/received_events", "type": "User", "site_admin": false}, "assignees": [{"login": "rchen152", "id": 4142312, "node_id": "MDQ6VXNlcjQxNDIzMTI=", "avatar_url": "https://avatars2.githubusercontent.com/u/4142312?v=4", "gravatar_id": "", "url": "https://api.github.com/users/rchen152", "html_url": "https://github.com/rchen152", "followers_url": "https://api.github.com/users/rchen152/followers", "following_url": "https://api.github.com/users/rchen152/following{/other_user}", "gists_url": "https://api.github.com/users/rchen152/gists{/gist_id}", "starred_url": "https://api.github.com/users/rchen152/starred{/owner}{/repo}", "subscriptions_url": "https://api.github.com/users/rchen152/subscriptions", "organizations_url": "https://api.github.com/users/rchen152/orgs", "repos_url": "https://api.github.com/users/rchen152/repos", "events_url": "https://api.github.com/users/rchen152/events{/privacy}", "received_events_url": "https://api.github.com/users/rchen152/received_events", "type": "User", "site_admin": false}], "milestone": null, "comments": 0, "created_at": "2018-12-14T00:51:22Z", "updated_at": "2018-12-26T18:42:36Z", "closed_at": "2018-12-26T18:42:36Z", "author_association": "COLLABORATOR", "active_lock_reason": null, "body": "Reproduce with:\r\n```\r\ngit clone git@github.com:GoogleCloudPlatform/django-cloud-deploy.git\r\ncd django-cloud-deploy\r\npip install .\r\nimportlab --tree django-cloud-deploy/cloudlib/database.py\r\n```\r\nimportlab reports:\r\n```\r\nReading 1 files\r\nSource tree:\r\n\r\nUnreadable files:\r\n  /usr/local/google/home/rechen/django-cloud-deploy/django_cloud_deploy/cloudlib/database.py\r\n```\r\nIn fact, database.py is readable, but a file in one of its pip-installed dependencies (django/contrib/auth/models.py) throws an error at import time.\r\n* importlab should mark models.py instead of database.py as unreadable.\r\n* It would be useful to surface the actual error that occurred, to give the user a better idea of why the file is unreadable.", "performed_via_github_app": null, "score": 1.0}, {"url": "https://api.github.com/repos/google/importlab/issues/34", "repository_url": "https://api.github.com/repos/google/importlab", "labels_url": "https://api.github.com/repos/google/importlab/issues/34/labels{/name}", "comments_url": "https://api.github.com/repos/google/importlab/issues/34/comments", "events_url": "https://api.github.com/repos/google/importlab/issues/34/events", "html_url": "https://github.com/google/importlab/issues/34", "id": 383231815, "node_id": "MDU6SXNzdWUzODMyMzE4MTU=", "number": 34, "title": "use strongly connected component detection in the graph builder", "user": {"login": "martindemello", "id": 16215, "node_id": "MDQ6VXNlcjE2MjE1", "avatar_url": "https://avatars2.githubusercontent.com/u/16215?v=4", "gravatar_id": "", "url": "https://api.github.com/users/martindemello", "html_url": "https://github.com/martindemello", "followers_url": "https://api.github.com/users/martindemello/followers", "following_url": "https://api.github.com/users/martindemello/following{/other_user}", "gists_url": "https://api.github.com/users/martindemello/gists{/gist_id}", "starred_url": "https://api.github.com/users/martindemello/starred{/owner}{/repo}", "subscriptions_url": "https://api.github.com/users/martindemello/subscriptions", "organizations_url": "https://api.github.com/users/martindemello/orgs", "repos_url": "https://api.github.com/users/martindemello/repos", "events_url": "https://api.github.com/users/martindemello/events{/privacy}", "received_events_url": "https://api.github.com/users/martindemello/received_events", "type": "User", "site_admin": false}, "labels": [{"id": 851814972, "node_id": "MDU6TGFiZWw4NTE4MTQ5NzI=", "url": "https://api.github.com/repos/google/importlab/labels/enhancement", "name": "enhancement", "color": "a2eeef", "default": true, "description": "New feature or request"}], "state": "closed", "locked": false, "assignee": null, "assignees": [], "milestone": null, "comments": 2, "created_at": "2018-11-21T17:49:30Z", "updated_at": "2018-12-21T05:46:43Z", "closed_at": "2018-12-21T05:46:42Z", "author_association": "COLLABORATOR", "active_lock_reason": null, "body": "[Kosaraju's algorithm](https://en.wikipedia.org/wiki/Kosaraju's_algorithm) is already [implemented in networkx](https://networkx.github.io/documentation/stable/reference/algorithms/generated/networkx.algorithms.components.kosaraju_strongly_connected_components.html), which could potentially simplify the cycle extraction code a lot.", "performed_via_github_app": null, "score": 1.0}, {"url": "https://api.github.com/repos/google/importlab/issues/33", "repository_url": "https://api.github.com/repos/google/importlab", "labels_url": "https://api.github.com/repos/google/importlab/issues/33/labels{/name}", "comments_url": "https://api.github.com/repos/google/importlab/issues/33/comments", "events_url": "https://api.github.com/repos/google/importlab/issues/33/events", "html_url": "https://github.com/google/importlab/issues/33", "id": 378080654, "node_id": "MDU6SXNzdWUzNzgwODA2NTQ=", "number": 33, "title": "Improve the default value of the --python-version option", "user": {"login": "rchen152", "id": 4142312, "node_id": "MDQ6VXNlcjQxNDIzMTI=", "avatar_url": "https://avatars2.githubusercontent.com/u/4142312?v=4", "gravatar_id": "", "url": "https://api.github.com/users/rchen152", "html_url": "https://github.com/rchen152", "followers_url": "https://api.github.com/users/rchen152/followers", "following_url": "https://api.github.com/users/rchen152/following{/other_user}", "gists_url": "https://api.github.com/users/rchen152/gists{/gist_id}", "starred_url": "https://api.github.com/users/rchen152/starred{/owner}{/repo}", "subscriptions_url": "https://api.github.com/users/rchen152/subscriptions", "organizations_url": "https://api.github.com/users/rchen152/orgs", "repos_url": "https://api.github.com/users/rchen152/repos", "events_url": "https://api.github.com/users/rchen152/events{/privacy}", "received_events_url": "https://api.github.com/users/rchen152/received_events", "type": "User", "site_admin": false}, "labels": [], "state": "closed", "locked": false, "assignee": null, "assignees": [], "milestone": null, "comments": 5, "created_at": "2018-11-06T23:38:42Z", "updated_at": "2018-12-21T23:01:32Z", "closed_at": "2018-12-21T23:01:32Z", "author_association": "COLLABORATOR", "active_lock_reason": null, "body": "EDIT: this post now demonstrates how easy it is to forget to set -V.\r\n\r\nRepro:\r\n```\r\necho \"import django\" > foo.py\r\necho \"import jinja2\" > bar.py\r\nvirtualenv --python=python3.5 .venv\r\nsource .venv/bin/activate\r\npip install importlab django jinja2\r\nimportlab --tree foo.py\r\nimportlab --tree bar.py\r\n```\r\nNeither dependency is found. Replace `python3.5` with `python3.6`, and both are found.", "performed_via_github_app": null, "score": 1.0}, {"url": "https://api.github.com/repos/google/importlab/issues/26", "repository_url": "https://api.github.com/repos/google/importlab", "labels_url": "https://api.github.com/repos/google/importlab/issues/26/labels{/name}", "comments_url": "https://api.github.com/repos/google/importlab/issues/26/comments", "events_url": "https://api.github.com/repos/google/importlab/issues/26/events", "html_url": "https://github.com/google/importlab/issues/26", "id": 362776822, "node_id": "MDU6SXNzdWUzNjI3NzY4MjI=", "number": 26, "title": "Can't find pip-installed google-auth in Python 2", "user": {"login": "rchen152", "id": 4142312, "node_id": "MDQ6VXNlcjQxNDIzMTI=", "avatar_url": "https://avatars2.githubusercontent.com/u/4142312?v=4", "gravatar_id": "", "url": "https://api.github.com/users/rchen152", "html_url": "https://github.com/rchen152", "followers_url": "https://api.github.com/users/rchen152/followers", "following_url": "https://api.github.com/users/rchen152/following{/other_user}", "gists_url": "https://api.github.com/users/rchen152/gists{/gist_id}", "starred_url": "https://api.github.com/users/rchen152/starred{/owner}{/repo}", "subscriptions_url": "https://api.github.com/users/rchen152/subscriptions", "organizations_url": "https://api.github.com/users/rchen152/orgs", "repos_url": "https://api.github.com/users/rchen152/repos", "events_url": "https://api.github.com/users/rchen152/events{/privacy}", "received_events_url": "https://api.github.com/users/rchen152/received_events", "type": "User", "site_admin": false}, "labels": [], "state": "closed", "locked": false, "assignee": null, "assignees": [], "milestone": null, "comments": 0, "created_at": "2018-09-21T21:15:49Z", "updated_at": "2018-10-03T22:04:13Z", "closed_at": "2018-10-03T22:04:13Z", "author_association": "COLLABORATOR", "active_lock_reason": null, "body": "In a Python 3.6 virtualenv:\r\n```\r\n$ pip install google-auth\r\n$ cat foo.py\r\nimport google.auth\r\n$ importlab --tree foo.py -V3.6\r\nReading 1 files\r\nSource tree:\r\n+ foo.py\r\n    :: google/auth/__init__.py\r\n    ...\r\n```\r\nBut in a Python 2.7 virtualenv:\r\n```\r\n$ pip install google-auth\r\n$ cat foo.py\r\nimport google.auth\r\n$ importlab --tree foo.py -V2.7\r\nReading 1 files\r\nSource tree:\r\n+ foo.py\r\n```", "performed_via_github_app": null, "score": 1.0}, {"url": "https://api.github.com/repos/google/importlab/issues/22", "repository_url": "https://api.github.com/repos/google/importlab", "labels_url": "https://api.github.com/repos/google/importlab/issues/22/labels{/name}", "comments_url": "https://api.github.com/repos/google/importlab/issues/22/comments", "events_url": "https://api.github.com/repos/google/importlab/issues/22/events", "html_url": "https://github.com/google/importlab/issues/22", "id": 359673583, "node_id": "MDU6SXNzdWUzNTk2NzM1ODM=", "number": 22, "title": "Incorrect inferred module name for __init__.py files", "user": {"login": "Solumin", "id": 930857, "node_id": "MDQ6VXNlcjkzMDg1Nw==", "avatar_url": "https://avatars0.githubusercontent.com/u/930857?v=4", "gravatar_id": "", "url": "https://api.github.com/users/Solumin", "html_url": "https://github.com/Solumin", "followers_url": "https://api.github.com/users/Solumin/followers", "following_url": "https://api.github.com/users/Solumin/following{/other_user}", "gists_url": "https://api.github.com/users/Solumin/gists{/gist_id}", "starred_url": "https://api.github.com/users/Solumin/starred{/owner}{/repo}", "subscriptions_url": "https://api.github.com/users/Solumin/subscriptions", "organizations_url": "https://api.github.com/users/Solumin/orgs", "repos_url": "https://api.github.com/users/Solumin/repos", "events_url": "https://api.github.com/users/Solumin/events{/privacy}", "received_events_url": "https://api.github.com/users/Solumin/received_events", "type": "User", "site_admin": false}, "labels": [], "state": "closed", "locked": false, "assignee": {"login": "Solumin", "id": 930857, "node_id": "MDQ6VXNlcjkzMDg1Nw==", "avatar_url": "https://avatars0.githubusercontent.com/u/930857?v=4", "gravatar_id": "", "url": "https://api.github.com/users/Solumin", "html_url": "https://github.com/Solumin", "followers_url": "https://api.github.com/users/Solumin/followers", "following_url": "https://api.github.com/users/Solumin/following{/other_user}", "gists_url": "https://api.github.com/users/Solumin/gists{/gist_id}", "starred_url": "https://api.github.com/users/Solumin/starred{/owner}{/repo}", "subscriptions_url": "https://api.github.com/users/Solumin/subscriptions", "organizations_url": "https://api.github.com/users/Solumin/orgs", "repos_url": "https://api.github.com/users/Solumin/repos", "events_url": "https://api.github.com/users/Solumin/events{/privacy}", "received_events_url": "https://api.github.com/users/Solumin/received_events", "type": "User", "site_admin": false}, "assignees": [{"login": "Solumin", "id": 930857, "node_id": "MDQ6VXNlcjkzMDg1Nw==", "avatar_url": "https://avatars0.githubusercontent.com/u/930857?v=4", "gravatar_id": "", "url": "https://api.github.com/users/Solumin", "html_url": "https://github.com/Solumin", "followers_url": "https://api.github.com/users/Solumin/followers", "following_url": "https://api.github.com/users/Solumin/following{/other_user}", "gists_url": "https://api.github.com/users/Solumin/gists{/gist_id}", "starred_url": "https://api.github.com/users/Solumin/starred{/owner}{/repo}", "subscriptions_url": "https://api.github.com/users/Solumin/subscriptions", "organizations_url": "https://api.github.com/users/Solumin/orgs", "repos_url": "https://api.github.com/users/Solumin/repos", "events_url": "https://api.github.com/users/Solumin/events{/privacy}", "received_events_url": "https://api.github.com/users/Solumin/received_events", "type": "User", "site_admin": false}], "milestone": null, "comments": 0, "created_at": "2018-09-12T22:21:11Z", "updated_at": "2018-09-12T22:42:54Z", "closed_at": "2018-09-12T22:42:54Z", "author_association": "CONTRIBUTOR", "active_lock_reason": null, "body": "See google/pytype#154 for more detail.\r\n\r\n`resolve.infer_module_name` calculates the wrong name for `__init__.py` files. For example, for `foo/bar/__init__.py`, it will return `foo.bar.__init__`. The module name should be `foo.bar`.", "performed_via_github_app": null, "score": 1.0}, {"url": "https://api.github.com/repos/google/importlab/issues/19", "repository_url": "https://api.github.com/repos/google/importlab", "labels_url": "https://api.github.com/repos/google/importlab/issues/19/labels{/name}", "comments_url": "https://api.github.com/repos/google/importlab/issues/19/comments", "events_url": "https://api.github.com/repos/google/importlab/issues/19/events", "html_url": "https://github.com/google/importlab/issues/19", "id": 358309868, "node_id": "MDU6SXNzdWUzNTgzMDk4Njg=", "number": 19, "title": "importlab crashes on file with tensorflow import", "user": {"login": "uriva", "id": 2490655, "node_id": "MDQ6VXNlcjI0OTA2NTU=", "avatar_url": "https://avatars2.githubusercontent.com/u/2490655?v=4", "gravatar_id": "", "url": "https://api.github.com/users/uriva", "html_url": "https://github.com/uriva", "followers_url": "https://api.github.com/users/uriva/followers", "following_url": "https://api.github.com/users/uriva/following{/other_user}", "gists_url": "https://api.github.com/users/uriva/gists{/gist_id}", "starred_url": "https://api.github.com/users/uriva/starred{/owner}{/repo}", "subscriptions_url": "https://api.github.com/users/uriva/subscriptions", "organizations_url": "https://api.github.com/users/uriva/orgs", "repos_url": "https://api.github.com/users/uriva/repos", "events_url": "https://api.github.com/users/uriva/events{/privacy}", "received_events_url": "https://api.github.com/users/uriva/received_events", "type": "User", "site_admin": false}, "labels": [], "state": "closed", "locked": false, "assignee": null, "assignees": [], "milestone": null, "comments": 6, "created_at": "2018-09-08T16:36:50Z", "updated_at": "2018-10-03T23:06:05Z", "closed_at": "2018-10-03T23:06:04Z", "author_association": "NONE", "active_lock_reason": null, "body": "importlab version: 0.3.0\r\n\r\nWhen running `importlab my_file.py --tree` on a file with contents `import tensorflow`, the result is the following exception:\r\n```\r\nReading 1 files\r\n/home/me/.local/lib/python3.6/site-packages/IPython/kernel/__init__.py:13: ShimWarning: The `IPython.kernel` package has been deprecated since IPython 4.0.You should import from ipykernel or jupyter_client instead.\r\n  \"You should import from ipykernel or jupyter_client instead.\", ShimWarning)\r\nTraceback (most recent call last):\r\n  File \"/usr/local/bin/importlab\", line 79, in <module>\r\n    sys.exit(main())\r\n  File \"/usr/local/bin/importlab\", line 63, in main\r\n    import_graph = graph.ImportGraph.create(env, args.inputs)\r\n  File \"/usr/local/lib/python3.6/dist-packages/importlab/graph.py\", line 258, in create\r\n    import_graph.add_file_recursive(os.path.abspath(filename))\r\n  File \"/usr/local/lib/python3.6/dist-packages/importlab/graph.py\", line 128, in add_file_recursive\r\n    deps, broken = self.get_file_deps(filename)\r\n  File \"/usr/local/lib/python3.6/dist-packages/importlab/graph.py\", line 272, in get_file_deps\r\n    for imp in parsepy.get_imports(filename, self.env.python_version):\r\n  File \"/usr/local/lib/python3.6/dist-packages/importlab/parsepy.py\", line 79, in get_imports\r\n    imports = import_finder.get_imports(filename)\r\n  File \"/usr/local/lib/python3.6/dist-packages/importlab/import_finder.py\", line 136, in get_imports\r\n    imports.append(i + (resolve_import(name, is_from, is_star),))\r\n  File \"/usr/local/lib/python3.6/dist-packages/importlab/import_finder.py\", line 116, in resolve_import\r\n    ret = _resolve_import(name)\r\n  File \"/usr/local/lib/python3.6/dist-packages/importlab/import_finder.py\", line 98, in _resolve_import\r\n    return _resolve_import_3(name)\r\n  File \"/usr/local/lib/python3.6/dist-packages/importlab/import_finder.py\", line 80, in _resolve_import_3\r\n    spec = importlib.util.find_spec(name)  # pytype: disable=module-attr\r\n  File \"/usr/lib/python3.6/importlib/util.py\", line 88, in find_spec\r\n    parent = __import__(parent_name, fromlist=['__path__'])\r\n  File \"/home/me/.local/lib/python3.6/site-packages/IPython/utils/_process_win32.py\", line 23, in <module>\r\n    from ctypes.wintypes import LPCWSTR, HLOCAL\r\n  File \"/usr/lib/python3.6/ctypes/wintypes.py\", line 20, in <module>\r\n    class VARIANT_BOOL(ctypes._SimpleCData):\r\nValueError: _type_ 'v' not supported\r\n\r\n```", "performed_via_github_app": null, "score": 1.0}, {"url": "https://api.github.com/repos/google/importlab/issues/16", "repository_url": "https://api.github.com/repos/google/importlab", "labels_url": "https://api.github.com/repos/google/importlab/issues/16/labels{/name}", "comments_url": "https://api.github.com/repos/google/importlab/issues/16/comments", "events_url": "https://api.github.com/repos/google/importlab/issues/16/events", "html_url": "https://github.com/google/importlab/issues/16", "id": 353133434, "node_id": "MDU6SXNzdWUzNTMxMzM0MzQ=", "number": 16, "title": "Crash when analyzing files of different Python versions", "user": {"login": "Solumin", "id": 930857, "node_id": "MDQ6VXNlcjkzMDg1Nw==", "avatar_url": "https://avatars0.githubusercontent.com/u/930857?v=4", "gravatar_id": "", "url": "https://api.github.com/users/Solumin", "html_url": "https://github.com/Solumin", "followers_url": "https://api.github.com/users/Solumin/followers", "following_url": "https://api.github.com/users/Solumin/following{/other_user}", "gists_url": "https://api.github.com/users/Solumin/gists{/gist_id}", "starred_url": "https://api.github.com/users/Solumin/starred{/owner}{/repo}", "subscriptions_url": "https://api.github.com/users/Solumin/subscriptions", "organizations_url": "https://api.github.com/users/Solumin/orgs", "repos_url": "https://api.github.com/users/Solumin/repos", "events_url": "https://api.github.com/users/Solumin/events{/privacy}", "received_events_url": "https://api.github.com/users/Solumin/received_events", "type": "User", "site_admin": false}, "labels": [], "state": "closed", "locked": false, "assignee": null, "assignees": [], "milestone": null, "comments": 0, "created_at": "2018-08-22T21:31:43Z", "updated_at": "2018-08-23T18:59:22Z", "closed_at": "2018-08-23T18:59:22Z", "author_association": "CONTRIBUTOR", "active_lock_reason": null, "body": "Input:\r\n```\r\n# file a.py\r\nimport b\r\n\r\n# file b.py\r\nraise 1, 2, 3  # Python 2 syntax\r\n```\r\n\r\nOutput of -V2.7:\r\n```\r\n$ importlab -V2.7 -P. *.py --tree\r\nSource tree:\r\n+ a.py\r\n    + b.py\r\n```\r\n\r\nOutput of -V3.6:\r\n```\r\n$ importlab -V3.6 -P. *.py --tree\r\nTraceback (most recent call last):\r\n  File \"/usr/bin/importlab\", line 69, in <module>\r\n    sys.exit(main())\r\n  File \"/usr/bin/importlab\", line 53, in main\r\n    import_graph = graph.ImportGraph.create(env, args.filenames)\r\n  File \"/usr/local/lib/python2.7/site-packages/importlab/graph.py\", line 248, in create\r\n    import_graph.add_file_recursive(os.path.abspath(filename))\r\n  File \"/usr/local/lib/python2.7/site-packages/importlab/graph.py\", line 123, in add_file_recursive\r\n    deps, broken = self.get_file_deps(filename)\r\n  File \"/usr/local/lib/python2.7/site-packages/importlab/graph.py\", line 262, in get_file_deps\r\n    for imp in parsepy.get_imports(filename, self.env.python_version):\r\n  File \"/usr/local/lib/python2.7/site-packages/importlab/parsepy.py\", line 90, in get_imports\r\n    raise Exception('parse error for ' + filename)\r\nException: parse error for /tmp/imptest/b.py\r\n```\r\n\r\nIt would be nice if importlab didn't crash here. I think a `--keep-going` option would be useful for some users.", "performed_via_github_app": null, "score": 1.0}, {"url": "https://api.github.com/repos/google/importlab/issues/15", "repository_url": "https://api.github.com/repos/google/importlab", "labels_url": "https://api.github.com/repos/google/importlab/issues/15/labels{/name}", "comments_url": "https://api.github.com/repos/google/importlab/issues/15/comments", "events_url": "https://api.github.com/repos/google/importlab/issues/15/events", "html_url": "https://github.com/google/importlab/issues/15", "id": 351401423, "node_id": "MDU6SXNzdWUzNTE0MDE0MjM=", "number": 15, "title": "importlab interacts badly with `pyenv local`", "user": {"login": "Solumin", "id": 930857, "node_id": "MDQ6VXNlcjkzMDg1Nw==", "avatar_url": "https://avatars0.githubusercontent.com/u/930857?v=4", "gravatar_id": "", "url": "https://api.github.com/users/Solumin", "html_url": "https://github.com/Solumin", "followers_url": "https://api.github.com/users/Solumin/followers", "following_url": "https://api.github.com/users/Solumin/following{/other_user}", "gists_url": "https://api.github.com/users/Solumin/gists{/gist_id}", "starred_url": "https://api.github.com/users/Solumin/starred{/owner}{/repo}", "subscriptions_url": "https://api.github.com/users/Solumin/subscriptions", "organizations_url": "https://api.github.com/users/Solumin/orgs", "repos_url": "https://api.github.com/users/Solumin/repos", "events_url": "https://api.github.com/users/Solumin/events{/privacy}", "received_events_url": "https://api.github.com/users/Solumin/received_events", "type": "User", "site_admin": false}, "labels": [], "state": "closed", "locked": false, "assignee": null, "assignees": [], "milestone": null, "comments": 4, "created_at": "2018-08-16T23:19:36Z", "updated_at": "2018-10-03T23:14:09Z", "closed_at": "2018-10-03T23:14:09Z", "author_association": "CONTRIBUTOR", "active_lock_reason": null, "body": "```shell\r\n$ virtualenv testbug\r\nNew python executable in testbug/bin/python\r\nInstalling setuptools, pip, wheel...done.\r\n$ source testbug/bin/activate\r\n$ echo \"import rsa\" > /tmp/test_rsa.py\r\n$ pip install pytype\r\nCollecting pytype\r\nCollecting six (from pytype)\r\n  Using cached https://files.pythonhosted.org/packages/67/4b/141a581104b1f6397bfa78ac9d43d8ad29a7ca43ea90a2d863fe3056e86a/six-1.11.0-py2.py3-none-any.whl\r\nCollecting importlab (from pytype)\r\nCollecting pyyaml>=3.11 (from pytype)\r\nCollecting networkx (from importlab->pytype)\r\nCollecting decorator>=4.1.0 (from networkx->importlab->pytype)\r\n  Using cached https://files.pythonhosted.org/packages/bc/bb/a24838832ba35baf52f32ab1a49b906b5f82fb7c76b2f6a7e35e140bac30/decorator-4.3.0-py2.py3-none-any.whl\r\nInstalling collected packages: six, decorator, networkx, importlab, pyyaml, pytype\r\nSuccessfully installed decorator-4.3.0 importlab-0.2.1 networkx-2.1 pytype-2018.8.10 pyyaml-3.13 six-1.11.0\r\n$ pytype -P /tmp /tmp/test_rsa.py\r\nAnalyzing 1 sources with 0 dependencies\r\nFile \"/tmp/test_rsa.py\", line 1, in <module>: Can't find module 'rsa'. [import-error]\r\n\r\nFor more details, see https://github.com/google/pytype/blob/master/docs/errors.md#import-error.\r\n$ pip install rsa\r\nCollecting rsa\r\n  Using cached https://files.pythonhosted.org/packages/e1/ae/baedc9cb175552e95f3395c43055a6a5e125ae4d48a1d7a924baca83e92e/rsa-3.4.2-py2.py3-none-any.whl\r\nCollecting pyasn1>=0.1.3 (from rsa)\r\n  Using cached https://files.pythonhosted.org/packages/d1/a1/7790cc85db38daa874f6a2e6308131b9953feb1367f2ae2d1123bb93a9f5/pyasn1-0.4.4-py2.py3-none-any.whl\r\nInstalling collected packages: pyasn1, rsa\r\nSuccessfully installed pyasn1-0.4.4 rsa-3.4.2\r\n$ pytype -P /tmp /tmp/test_rsa.py\r\nAnalyzing 1 sources with 0 dependencies\r\nFile \"/tmp/test_rsa.py\", line 1, in <module>: Can't find module 'rsa'. [import-error]\r\n\r\nFor more details, see https://github.com/google/pytype/blob/master/docs/errors.md#import-error.\r\n$ python /tmp/test_rsa.py\r\n$ importlab /tmp/test_rsa.py --unresolved\r\nUnresolved dependencies:\r\n  rsa\r\n```", "performed_via_github_app": null, "score": 1.0}, {"url": "https://api.github.com/repos/google/importlab/issues/12", "repository_url": "https://api.github.com/repos/google/importlab", "labels_url": "https://api.github.com/repos/google/importlab/issues/12/labels{/name}", "comments_url": "https://api.github.com/repos/google/importlab/issues/12/comments", "events_url": "https://api.github.com/repos/google/importlab/issues/12/events", "html_url": "https://github.com/google/importlab/issues/12", "id": 351314996, "node_id": "MDU6SXNzdWUzNTEzMTQ5OTY=", "number": 12, "title": "Importlab doesn't work when passed a directory.", "user": {"login": "Solumin", "id": 930857, "node_id": "MDQ6VXNlcjkzMDg1Nw==", "avatar_url": "https://avatars0.githubusercontent.com/u/930857?v=4", "gravatar_id": "", "url": "https://api.github.com/users/Solumin", "html_url": "https://github.com/Solumin", "followers_url": "https://api.github.com/users/Solumin/followers", "following_url": "https://api.github.com/users/Solumin/following{/other_user}", "gists_url": "https://api.github.com/users/Solumin/gists{/gist_id}", "starred_url": "https://api.github.com/users/Solumin/starred{/owner}{/repo}", "subscriptions_url": "https://api.github.com/users/Solumin/subscriptions", "organizations_url": "https://api.github.com/users/Solumin/orgs", "repos_url": "https://api.github.com/users/Solumin/repos", "events_url": "https://api.github.com/users/Solumin/events{/privacy}", "received_events_url": "https://api.github.com/users/Solumin/received_events", "type": "User", "site_admin": false}, "labels": [], "state": "closed", "locked": false, "assignee": null, "assignees": [], "milestone": null, "comments": 0, "created_at": "2018-08-16T18:18:27Z", "updated_at": "2018-08-23T22:05:12Z", "closed_at": "2018-08-23T22:05:12Z", "author_association": "CONTRIBUTOR", "active_lock_reason": null, "body": "Command: `importlab google --unresolved`\r\n(Running in the [google-auth](https://github.com/GoogleCloudPlatform/google-auth-library-python) repository.)\r\n\r\nResult:\r\n```\r\nTraceback (most recent call last):\r\n  File \"/usr/local/google/home/tsudol/pytype-venv/bin/importlab\", line 69, in <module>\r\n    sys.exit(main())\r\n  File \"/usr/local/google/home/tsudol/pytype-venv/bin/importlab\", line 53, in main\r\n    import_graph = graph.ImportGraph.create(env, args.filenames)\r\n  File \"/usr/local/google/home/tsudol/pytype-venv/local/lib/python2.7/site-packages/importlab/graph.py\", line 248, in create\r\n    import_graph.add_file_recursive(os.path.abspath(filename))\r\n  File \"/usr/local/google/home/tsudol/pytype-venv/local/lib/python2.7/site-packages/importlab/graph.py\", line 123, in add_file_recursive\r\n    deps, broken = self.get_file_deps(filename)\r\n  File \"/usr/local/google/home/tsudol/pytype-venv/local/lib/python2.7/site-packages/importlab/graph.py\", line 262, in get_file_deps\r\n    for imp in parsepy.get_imports(filename, self.env.python_version):\r\n  File \"/usr/local/google/home/tsudol/pytype-venv/local/lib/python2.7/site-packages/importlab/parsepy.py\", line 90, in get_imports\r\n    raise Exception('parse error for ' + filename)\r\nException: parse error for /usr/local/google/home/tsudol/google-auth-library-python/google\r\n```\r\n\r\nExpected result:\r\nA list of all unresolved dependencies in the directory.\r\n\r\nRunning with `google/*.py` worked.", "performed_via_github_app": null, "score": 1.0}, {"url": "https://api.github.com/repos/google/importlab/issues/11", "repository_url": "https://api.github.com/repos/google/importlab", "labels_url": "https://api.github.com/repos/google/importlab/issues/11/labels{/name}", "comments_url": "https://api.github.com/repos/google/importlab/issues/11/comments", "events_url": "https://api.github.com/repos/google/importlab/issues/11/events", "html_url": "https://github.com/google/importlab/issues/11", "id": 351089832, "node_id": "MDU6SXNzdWUzNTEwODk4MzI=", "number": 11, "title": "Importlab running under Python 3.6 and analyzing Python 2.7 can't find networkx", "user": {"login": "rchen152", "id": 4142312, "node_id": "MDQ6VXNlcjQxNDIzMTI=", "avatar_url": "https://avatars2.githubusercontent.com/u/4142312?v=4", "gravatar_id": "", "url": "https://api.github.com/users/rchen152", "html_url": "https://github.com/rchen152", "followers_url": "https://api.github.com/users/rchen152/followers", "following_url": "https://api.github.com/users/rchen152/following{/other_user}", "gists_url": "https://api.github.com/users/rchen152/gists{/gist_id}", "starred_url": "https://api.github.com/users/rchen152/starred{/owner}{/repo}", "subscriptions_url": "https://api.github.com/users/rchen152/subscriptions", "organizations_url": "https://api.github.com/users/rchen152/orgs", "repos_url": "https://api.github.com/users/rchen152/repos", "events_url": "https://api.github.com/users/rchen152/events{/privacy}", "received_events_url": "https://api.github.com/users/rchen152/received_events", "type": "User", "site_admin": false}, "labels": [], "state": "closed", "locked": false, "assignee": null, "assignees": [], "milestone": null, "comments": 3, "created_at": "2018-08-16T07:38:45Z", "updated_at": "2018-08-16T21:45:42Z", "closed_at": "2018-08-16T21:45:42Z", "author_association": "COLLABORATOR", "active_lock_reason": null, "body": "Steps I took:\r\n\r\nsudo apt-get install python-pip\r\npip install networkx  # puts networkx in ~/.local/lib/python2.7/site-packages/\r\nvirtualenv --python=python3.6 .venv3\r\nsource .venv3/bin/activate\r\npip install importlab\r\necho \"import networkx\" > foo.py\r\nimportlab -V2.7 foo.py --tree\r\n\r\n`foo.py` shows up as the only file in the tree. On the other hand, if I install importlab under Python 2.7 and analyze Python 3.5 code (I didn't try 3.6 because pip3 is 3.5 on my machine), the last command (correctly) causes a bunch of networkx files to be printed as part of the tree.", "performed_via_github_app": null, "score": 1.0}, {"url": "https://api.github.com/repos/google/importlab/issues/1", "repository_url": "https://api.github.com/repos/google/importlab", "labels_url": "https://api.github.com/repos/google/importlab/issues/1/labels{/name}", "comments_url": "https://api.github.com/repos/google/importlab/issues/1/comments", "events_url": "https://api.github.com/repos/google/importlab/issues/1/events", "html_url": "https://github.com/google/importlab/issues/1", "id": 319738405, "node_id": "MDU6SXNzdWUzMTk3Mzg0MDU=", "number": 1, "title": "parsepy_test is broken", "user": {"login": "rchen152", "id": 4142312, "node_id": "MDQ6VXNlcjQxNDIzMTI=", "avatar_url": "https://avatars2.githubusercontent.com/u/4142312?v=4", "gravatar_id": "", "url": "https://api.github.com/users/rchen152", "html_url": "https://github.com/rchen152", "followers_url": "https://api.github.com/users/rchen152/followers", "following_url": "https://api.github.com/users/rchen152/following{/other_user}", "gists_url": "https://api.github.com/users/rchen152/gists{/gist_id}", "starred_url": "https://api.github.com/users/rchen152/starred{/owner}{/repo}", "subscriptions_url": "https://api.github.com/users/rchen152/subscriptions", "organizations_url": "https://api.github.com/users/rchen152/orgs", "repos_url": "https://api.github.com/users/rchen152/repos", "events_url": "https://api.github.com/users/rchen152/events{/privacy}", "received_events_url": "https://api.github.com/users/rchen152/received_events", "type": "User", "site_admin": false}, "labels": [], "state": "closed", "locked": false, "assignee": null, "assignees": [], "milestone": null, "comments": 1, "created_at": "2018-05-02T22:52:07Z", "updated_at": "2018-05-02T23:22:03Z", "closed_at": "2018-05-02T23:22:02Z", "author_association": "COLLABORATOR", "active_lock_reason": null, "body": "I executed `python -m importlab.parsepy_test` and got a bunch of errors of the following form:\r\n\r\n```\r\nERROR: test_simple (\\__main__.TestParsePy)\r\nTraceback (most recent call last):\r\n  File \"/usr/local/google/home/rechen/importlab/importlab/parsepy_test.py\", line 36, in test_simple\r\n    \"\"\"), [parsepy.ImportStatement(name=\"a\")])\r\n  File \"/usr/local/google/home/rechen/importlab/importlab/parsepy_test.py\", line 31, in parse\r\n    return parsepy.scan_string(textwrap.dedent(src))\r\nAttributeError: 'module' object has no attribute 'scan_string'\r\n```", "performed_via_github_app": null, "score": 1.0}]}