{"total_count": 2, "incomplete_results": false, "items": [{"url": "https://api.github.com/repos/sdispater/pastel/issues/5", "repository_url": "https://api.github.com/repos/sdispater/pastel", "labels_url": "https://api.github.com/repos/sdispater/pastel/issues/5/labels{/name}", "comments_url": "https://api.github.com/repos/sdispater/pastel/issues/5/comments", "events_url": "https://api.github.com/repos/sdispater/pastel/issues/5/events", "html_url": "https://github.com/sdispater/pastel/issues/5", "id": 403173848, "node_id": "MDU6SXNzdWU0MDMxNzM4NDg=", "number": 5, "title": "LICENSE/COPYING file missing from repository and pypi sources", "user": {"login": "decathorpe", "id": 12836693, "node_id": "MDQ6VXNlcjEyODM2Njkz", "avatar_url": "https://avatars2.githubusercontent.com/u/12836693?v=4", "gravatar_id": "", "url": "https://api.github.com/users/decathorpe", "html_url": "https://github.com/decathorpe", "followers_url": "https://api.github.com/users/decathorpe/followers", "following_url": "https://api.github.com/users/decathorpe/following{/other_user}", "gists_url": "https://api.github.com/users/decathorpe/gists{/gist_id}", "starred_url": "https://api.github.com/users/decathorpe/starred{/owner}{/repo}", "subscriptions_url": "https://api.github.com/users/decathorpe/subscriptions", "organizations_url": "https://api.github.com/users/decathorpe/orgs", "repos_url": "https://api.github.com/users/decathorpe/repos", "events_url": "https://api.github.com/users/decathorpe/events{/privacy}", "received_events_url": "https://api.github.com/users/decathorpe/received_events", "type": "User", "site_admin": false}, "labels": [], "state": "closed", "locked": false, "assignee": null, "assignees": [], "milestone": null, "comments": 6, "created_at": "2019-01-25T14:14:26Z", "updated_at": "2019-09-21T14:40:42Z", "closed_at": "2019-09-21T14:40:41Z", "author_association": "NONE", "active_lock_reason": null, "body": "I'm working on packaging this project for fedora, and during the review, it was pointed out that the repository and the sources that are available from PyPI don't include a COPYING / LICENSE file - which they apparently should to comply with rules for MIT-licensed projects.", "performed_via_github_app": null, "score": 1.0}, {"url": "https://api.github.com/repos/sdispater/pastel/issues/4", "repository_url": "https://api.github.com/repos/sdispater/pastel", "labels_url": "https://api.github.com/repos/sdispater/pastel/issues/4/labels{/name}", "comments_url": "https://api.github.com/repos/sdispater/pastel/issues/4/comments", "events_url": "https://api.github.com/repos/sdispater/pastel/issues/4/events", "html_url": "https://github.com/sdispater/pastel/issues/4", "id": 396566997, "node_id": "MDU6SXNzdWUzOTY1NjY5OTc=", "number": 4, "title": "Fails tests with Python3", "user": {"login": "jbaum98", "id": 5283991, "node_id": "MDQ6VXNlcjUyODM5OTE=", "avatar_url": "https://avatars0.githubusercontent.com/u/5283991?v=4", "gravatar_id": "", "url": "https://api.github.com/users/jbaum98", "html_url": "https://github.com/jbaum98", "followers_url": "https://api.github.com/users/jbaum98/followers", "following_url": "https://api.github.com/users/jbaum98/following{/other_user}", "gists_url": "https://api.github.com/users/jbaum98/gists{/gist_id}", "starred_url": "https://api.github.com/users/jbaum98/starred{/owner}{/repo}", "subscriptions_url": "https://api.github.com/users/jbaum98/subscriptions", "organizations_url": "https://api.github.com/users/jbaum98/orgs", "repos_url": "https://api.github.com/users/jbaum98/repos", "events_url": "https://api.github.com/users/jbaum98/events{/privacy}", "received_events_url": "https://api.github.com/users/jbaum98/received_events", "type": "User", "site_admin": false}, "labels": [], "state": "closed", "locked": false, "assignee": null, "assignees": [], "milestone": null, "comments": 1, "created_at": "2019-01-07T16:56:18Z", "updated_at": "2019-01-08T01:54:40Z", "closed_at": "2019-01-08T01:54:39Z", "author_association": "NONE", "active_lock_reason": null, "body": "I'm packaging `pastel` for `nixpkgs` and for Python3, and the tests are failing with\r\n\r\n```\r\nrunning egg_info\r\nwriting pastel.egg-info/PKG-INFO\r\nwriting dependency_links to pastel.egg-info/dependency_links.txt\r\nwriting top-level names to pastel.egg-info/top_level.txt\r\nreading manifest file 'pastel.egg-info/SOURCES.txt'\r\nwriting manifest file 'pastel.egg-info/SOURCES.txt'\r\nrunning build_ext\r\nTraceback (most recent call last):\r\n  File \"nix_run_setup\", line 8, in <module>\r\n    exec(compile(getattr(tokenize, 'open', open)(__file__).read().replace('\\\\r\\\\n', '\\\\n'), __file__, 'exec'))\r\n  File \"setup.py\", line 51, in <module>\r\n    setup(**kwargs)\r\n  File \"/nix/store/r9asxjad4m81h4dmkhxlmqmk7p7xwbdf-python3.7-bootstrapped-pip-18.1/lib/python3.7/site-packages/setuptools/__init__.py\", line 143, in setup\r\n    return distutils.core.setup(**attrs)\r\n  File \"/nix/store/5di2wpc5h7faqidsikgb94rwdbwy2y3l-python3-3.7.2/lib/python3.7/distutils/core.py\", line 148, in setup\r\n    dist.run_commands()\r\n  File \"/nix/store/5di2wpc5h7faqidsikgb94rwdbwy2y3l-python3-3.7.2/lib/python3.7/distutils/dist.py\", line 966, in run_commands\r\n    self.run_command(cmd)\r\n  File \"/nix/store/5di2wpc5h7faqidsikgb94rwdbwy2y3l-python3-3.7.2/lib/python3.7/distutils/dist.py\", line 985, in run_command\r\n    cmd_obj.run()\r\n  File \"/nix/store/r9asxjad4m81h4dmkhxlmqmk7p7xwbdf-python3.7-bootstrapped-pip-18.1/lib/python3.7/site-packages/setuptools/command/test.py\", line 228, in run\r\n    self.run_tests()\r\n  File \"/nix/store/r9asxjad4m81h4dmkhxlmqmk7p7xwbdf-python3.7-bootstrapped-pip-18.1/lib/python3.7/site-packages/setuptools/command/test.py\", line 250, in run_tests\r\n    exit=False,\r\n  File \"/nix/store/5di2wpc5h7faqidsikgb94rwdbwy2y3l-python3-3.7.2/lib/python3.7/unittest/main.py\", line 100, in __init__\r\n    self.parseArgs(argv)\r\n  File \"/nix/store/5di2wpc5h7faqidsikgb94rwdbwy2y3l-python3-3.7.2/lib/python3.7/unittest/main.py\", line 124, in parseArgs\r\n    self._do_discovery(argv[2:])\r\n  File \"/nix/store/5di2wpc5h7faqidsikgb94rwdbwy2y3l-python3-3.7.2/lib/python3.7/unittest/main.py\", line 244, in _do_discovery\r\n    self.createTests(from_discovery=True, Loader=Loader)\r\n  File \"/nix/store/5di2wpc5h7faqidsikgb94rwdbwy2y3l-python3-3.7.2/lib/python3.7/unittest/main.py\", line 154, in createTests\r\n    self.test = loader.discover(self.start, self.pattern, self.top)\r\n  File \"/nix/store/5di2wpc5h7faqidsikgb94rwdbwy2y3l-python3-3.7.2/lib/python3.7/unittest/loader.py\", line 347, in discover\r\n    tests = list(self._find_tests(start_dir, pattern))\r\n  File \"/nix/store/5di2wpc5h7faqidsikgb94rwdbwy2y3l-python3-3.7.2/lib/python3.7/unittest/loader.py\", line 404, in _find_tests\r\n    full_path, pattern, namespace)\r\n  File \"/nix/store/5di2wpc5h7faqidsikgb94rwdbwy2y3l-python3-3.7.2/lib/python3.7/unittest/loader.py\", line 481, in _find_test_path\r\n    tests = self.loadTestsFromModule(package, pattern=pattern)\r\n  File \"/nix/store/r9asxjad4m81h4dmkhxlmqmk7p7xwbdf-python3.7-bootstrapped-pip-18.1/lib/python3.7/site-packages/setuptools/command/test.py\", line 54, in loadTestsFromModule\r\n    tests.append(self.loadTestsFromName(submodule))\r\n  File \"/nix/store/5di2wpc5h7faqidsikgb94rwdbwy2y3l-python3-3.7.2/lib/python3.7/unittest/loader.py\", line 212, in loadTestsFromName\r\n    (obj, test))\r\nTypeError: calling <function pastel at 0x7ffff1adb6a8> returned <pastel.pastel.Pastel object at 0x7ffff1acf860>, not a test\r\n```", "performed_via_github_app": null, "score": 1.0}]}